Workbook

Sheet Annual Summary
B2: Family Book v2.0 by SkybatanX: a yearly family income & expense book run by your personal Grok Bot. The bot sets up each year's book and logs spending from card statements, bank transactions when you share them, and receipts. Each month keeps the number grid, then a Transactions section and a Receipts section. The same purchase is never added twice. Follow @SkyXFunNext on X for more templates and fun!
B5: Enter year
B7: Monthly Totals
C8: Jan | D8: Feb | E8: Mar | F8: Apr | G8: May | H8: Jun | I8: Jul | J8: Aug | K8: Sep | L8: Oct | M8: Nov | N8: Dec | O8: Annual Total
B9: Monthly Balance | C9: =Jan!$F$18 | D9: =Feb!$F$18 | E9: =Mar!$F$18 | F9: =Apr!$F$18 | G9: =May!$F$18 | H9: =Jun!$F$18 | I9: =Jul!$F$18 | J9: =Aug!$F$18 | K9: =Sep!$F$18 | L9: =Oct!$F$18 | M9: =Nov!$F$18 | N9: =Dec!$F$18 | O9: =SUM(C9:N9)
B11: Expenses by Category | C11: CAD
B12: Item | C12: Jan | D12: Feb | E12: Mar | F12: Apr | G12: May | H12: Jun | I12: Jul | J12: Aug | K12: Sep | L12: Oct | M12: Nov | N12: Dec | O12: Annual Total | P12: Share of Expenses
B13: Food (Meals) | C13: =Jan!$G$8-C14 | D13: =Feb!$G$8-D14 | E13: =Mar!$G$8-E14 | F13: =Apr!$G$8-F14 | G13: =May!$G$8-G14 | H13: =Jun!$G$8-H14 | I13: =Jul!$G$8-I14 | J13: =Aug!$G$8-J14 | K13: =Sep!$G$8-K14 | L13: =Oct!$G$8-L14 | M13: =Nov!$G$8-M14 | N13: =Dec!$G$8-N14 | O13: =SUM(C13:N13) | P13: =IF(ISERROR(O13/SUM($O$13:$O$37)),"%",O13/SUM($O$13:$O$37))
B14: Snacks & Groceries | C14: =SUM(Jan!$J$17:$BS$19) | D14: =SUM(Feb!$J$17:$BS$19) | E14: =SUM(Mar!$J$17:$BS$19) | F14: =SUM(Apr!$J$17:$BS$19) | G14: =SUM(May!$J$17:$BS$19) | H14: =SUM(Jun!$J$17:$BS$19) | I14: =SUM(Jul!$J$17:$BS$19) | J14: =SUM(Aug!$J$17:$BS$19) | K14: =SUM(Sep!$J$17:$BS$19) | L14: =SUM(Oct!$J$17:$BS$19) | M14: =SUM(Nov!$J$17:$BS$19) | N14: =SUM(Dec!$J$17:$BS$19) | O14: =SUM(C14:N14) | P14: =IF(ISERROR(O14/SUM($O$13:$O$37)),"%",O14/SUM($O$13:$O$37))
B15: Household Goods | C15: =Jan!$G$9 | D15: =Feb!$G$9 | E15: =Mar!$G$9 | F15: =Apr!$G$9 | G15: =May!$G$9 | H15: =Jun!$G$9 | I15: =Jul!$G$9 | J15: =Aug!$G$9 | K15: =Sep!$G$9 | L15: =Oct!$G$9 | M15: =Nov!$G$9 | N15: =Dec!$G$9 | O15: =SUM(C15:N15) | P15: =IF(ISERROR(O15/SUM($O$13:$O$37)),"%",O15/SUM($O$13:$O$37))
B16: Education & Enrichment | C16: =Jan!$G$10 | D16: =Feb!$G$10 | E16: =Mar!$G$10 | F16: =Apr!$G$10 | G16: =May!$G$10 | H16: =Jun!$G$10 | I16: =Jul!$G$10 | J16: =Aug!$G$10 | K16: =Sep!$G$10 | L16: =Oct!$G$10 | M16: =Nov!$G$10 | N16: =Dec!$G$10 | O16: =SUM(C16:N16) | P16: =IF(ISERROR(O16/SUM($O$13:$O$37)),"%",O16/SUM($O$13:$O$37))
B17: Fuel | C17: =SUM(Jan!$J$29:$BS$29) | D17: =SUM(Feb!$J$29:$BS$29) | E17: =SUM(Mar!$J$29:$BS$29) | F17: =SUM(Apr!$J$29:$BS$29) | G17: =SUM(May!$J$29:$BS$29) | H17: =SUM(Jun!$J$29:$BS$29) | I17: =SUM(Jul!$J$29:$BS$29) | J17: =SUM(Aug!$J$29:$BS$29) | K17: =SUM(Sep!$J$29:$BS$29) | L17: =SUM(Oct!$J$29:$BS$29) | M17: =SUM(Nov!$J$29:$BS$29) | N17: =SUM(Dec!$J$29:$BS$29) | O17: =SUM(C17:N17) | P17: =IF(ISERROR(O17/SUM($O$13:$O$37)),"%",O17/SUM($O$13:$O$37))
B18: Clothing | C18: =SUM(Jan!J30:BS31) | D18: =SUM(Feb!K30:BS31) | E18: =SUM(Mar!K30:BS31) | F18: =SUM(Apr!K30:BS31) | G18: =SUM(May!K30:BS31) | H18: =SUM(Jun!K30:BS31) | I18: =SUM(Jul!K30:BS31) | J18: =SUM(Aug!K30:BS31) | K18: =SUM(Sep!K30:BS31) | L18: =SUM(Oct!K30:BS31) | M18: =SUM(Nov!K30:BS31) | N18: =SUM(Dec!K30:BS31) | O18: =SUM(C18:N18) | P18: =IF(ISERROR(O18/SUM($O$13:$O$37)),"%",O18/SUM($O$13:$O$37))
B19: Medical | C19: =SUM(Jan!J32:BS32) | D19: =SUM(Feb!K32:BS32) | E19: =SUM(Mar!K32:BS32) | F19: =SUM(Apr!K32:BS32) | G19: =SUM(May!K32:BS32) | H19: =SUM(Jun!K32:BS32) | I19: =SUM(Jul!K32:BS32) | J19: =SUM(Aug!K32:BS32) | K19: =SUM(Sep!K32:BS32) | L19: =SUM(Oct!K32:BS32) | M19: =SUM(Nov!K32:BS32) | N19: =SUM(Dec!K32:BS32) | O19: =SUM(C19:N19) | P19: =IF(ISERROR(O19/SUM($O$13:$O$37)),"%",O19/SUM($O$13:$O$37))
B20: Hair & Cosmetics | C20: =SUM(Jan!J33:BS33) | D20: =SUM(Feb!K33:BS33) | E20: =SUM(Mar!K33:BS33) | F20: =SUM(Apr!K33:BS33) | G20: =SUM(May!K33:BS33) | H20: =SUM(Jun!K33:BS33) | I20: =SUM(Jul!K33:BS33) | J20: =SUM(Aug!K33:BS33) | K20: =SUM(Sep!K33:BS33) | L20: =SUM(Oct!K33:BS33) | M20: =SUM(Nov!K33:BS33) | N20: =SUM(Dec!K33:BS33) | O20: =SUM(C20:N20) | P20: =IF(ISERROR(O20/SUM($O$13:$O$37)),"%",O20/SUM($O$13:$O$37))
B21: Transportation | C21: =SUM(Jan!J34:BS34) | D21: =SUM(Feb!K34:BS34) | E21: =SUM(Mar!K34:BS34) | F21: =SUM(Apr!K34:BS34) | G21: =SUM(May!K34:BS34) | H21: =SUM(Jun!K34:BS34) | I21: =SUM(Jul!K34:BS34) | J21: =SUM(Aug!K34:BS34) | K21: =SUM(Sep!K34:BS34) | L21: =SUM(Oct!K34:BS34) | M21: =SUM(Nov!K34:BS34) | N21: =SUM(Dec!K34:BS34) | O21: =SUM(C21:N21) | P21: =IF(ISERROR(O21/SUM($O$13:$O$37)),"%",O21/SUM($O$13:$O$37))
B22: Entertainment | C22: =SUM(Jan!J35:BS35) | D22: =SUM(Feb!K35:BS35) | E22: =SUM(Mar!K35:BS35) | F22: =SUM(Apr!K35:BS35) | G22: =SUM(May!K35:BS35) | H22: =SUM(Jun!K35:BS35) | I22: =SUM(Jul!K35:BS35) | J22: =SUM(Aug!K35:BS35) | K22: =SUM(Sep!K35:BS35) | L22: =SUM(Oct!K35:BS35) | M22: =SUM(Nov!K35:BS35) | N22: =SUM(Dec!K35:BS35) | O22: =SUM(C22:N22) | P22: =IF(ISERROR(O22/SUM($O$13:$O$37)),"%",O22/SUM($O$13:$O$37))
B23: Gifts & Social | C23: =SUM(Jan!J36:BS36) | D23: =SUM(Feb!K36:BS36) | E23: =SUM(Mar!K36:BS36) | F23: =SUM(Apr!K36:BS36) | G23: =SUM(May!K36:BS36) | H23: =SUM(Jun!K36:BS36) | I23: =SUM(Jul!K36:BS36) | J23: =SUM(Aug!K36:BS36) | K23: =SUM(Sep!K36:BS36) | L23: =SUM(Oct!K36:BS36) | M23: =SUM(Nov!K36:BS36) | N23: =SUM(Dec!K36:BS36) | O23: =SUM(C23:N23) | P23: =IF(ISERROR(O23/SUM($O$13:$O$37)),"%",O23/SUM($O$13:$O$37))
B24: Income offset | C24: =Jan!C18 | D24: =Feb!C18 | E24: =Mar!C18 | F24: =Apr!C18 | G24: =May!C18 | H24: =Jun!C18 | I24: =Jul!C18 | J24: =Aug!C18 | K24: =Sep!C18 | L24: =Oct!C18 | M24: =Nov!C18 | N24: =Dec!C18 | O24: =SUM(C24:N24) | P24: =IF(ISERROR(O24/SUM($O$13:$O$37)),"%",O24/SUM($O$13:$O$37))
B25: GAS | C25: =Jan!C19 | D25: =Feb!C19 | E25: =Mar!C19 | F25: =Apr!C19 | G25: =May!C19 | H25: =Jun!C19 | I25: =Jul!C19 | J25: =Aug!C19 | K25: =Sep!C19 | L25: =Oct!C19 | M25: =Nov!C19 | N25: =Dec!C19 | O25: =SUM(C25:N25) | P25: =IF(ISERROR(O25/SUM($O$13:$O$37)),"%",O25/SUM($O$13:$O$37))
B26: Electricity & Water | C26: =Jan!C20 | D26: =Feb!C20 | E26: =Mar!C20 | F26: =Apr!C20 | G26: =May!C20 | H26: =Jun!C20 | I26: =Jul!C20 | J26: =Aug!C20 | K26: =Sep!C20 | L26: =Oct!C20 | M26: =Nov!C20 | N26: =Dec!C20 | O26: =SUM(C26:N26) | P26: =IF(ISERROR(O26/SUM($O$13:$O$37)),"%",O26/SUM($O$13:$O$37))
B27: RESP | C27: =Jan!C21 | D27: =Feb!C21 | E27: =Mar!C21 | F27: =Apr!C21 | G27: =May!C21 | H27: =Jun!C21 | I27: =Jul!C21 | J27: =Aug!C21 | K27: =Sep!C21 | L27: =Oct!C21 | M27: =Nov!C21 | N27: =Dec!C21 | O27: =SUM(C27:N27) | P27: =IF(ISERROR(O27/SUM($O$13:$O$37)),"%",O27/SUM($O$13:$O$37))
B28: Mobile Phone | C28: =Jan!C22 | D28: =Feb!C22 | E28: =Mar!C22 | F28: =Apr!C22 | G28: =May!C22 | H28: =Jun!C22 | I28: =Jul!C22 | J28: =Aug!C22 | K28: =Sep!C22 | L28: =Oct!C22 | M28: =Nov!C22 | N28: =Dec!C22 | O28: =SUM(C28:N28) | P28: =IF(ISERROR(O28/SUM($O$13:$O$37)),"%",O28/SUM($O$13:$O$37))
B29: Daycare | C29: =Jan!C23 | D29: =Feb!C23 | E29: =Mar!C23 | F29: =Apr!C23 | G29: =May!C23 | H29: =Jun!C23 | I29: =Jul!C23 | J29: =Aug!C23 | K29: =Sep!C23 | L29: =Oct!C23 | M29: =Nov!C23 | N29: =Dec!C23 | O29: =SUM(C29:N29) | P29: =IF(ISERROR(O29/SUM($O$13:$O$37)),"%",O29/SUM($O$13:$O$37))
B30: Rent / Mortgage | C30: =Jan!C24 | D30: =Feb!C24 | E30: =Mar!C24 | F30: =Apr!C24 | G30: =May!C24 | H30: =Jun!C24 | I30: =Jul!C24 | J30: =Aug!C24 | K30: =Sep!C24 | L30: =Oct!C24 | M30: =Nov!C24 | N30: =Dec!C24 | O30: =SUM(C30:N30) | P30: =IF(ISERROR(O30/SUM($O$13:$O$37)),"%",O30/SUM($O$13:$O$37))
B31: Internet | C31: =Jan!C25 | D31: =Feb!C25 | E31: =Mar!C25 | F31: =Apr!C25 | G31: =May!C25 | H31: =Jun!C25 | I31: =Jul!C25 | J31: =Aug!C25 | K31: =Sep!C25 | L31: =Oct!C25 | M31: =Nov!C25 | N31: =Dec!C25 | O31: =SUM(C31:N31) | P31: =IF(ISERROR(O31/SUM($O$13:$O$37)),"%",O31/SUM($O$13:$O$37))
B32: Car Insurance | C32: =Jan!C26 | D32: =Feb!C26 | E32: =Mar!C26 | F32: =Apr!C26 | G32: =May!C26 | H32: =Jun!C26 | I32: =Jul!C26 | J32: =Aug!C26 | K32: =Sep!C26 | L32: =Oct!C26 | M32: =Nov!C26 | N32: =Dec!C26 | O32: =SUM(C32:N32) | P32: =IF(ISERROR(O32/SUM($O$13:$O$37)),"%",O32/SUM($O$13:$O$37))
B33: Property Tax | C33: =Jan!C27 | D33: =Feb!C27 | E33: =Mar!C27 | F33: =Apr!C27 | G33: =May!C27 | H33: =Jun!C27 | I33: =Jul!C27 | J33: =Aug!C27 | K33: =Sep!C27 | L33: =Oct!C27 | M33: =Nov!C27 | N33: =Dec!C27 | O33: =SUM(C33:N33) | P33: =IF(ISERROR(O33/SUM($O$13:$O$37)),"%",O33/SUM($O$13:$O$37))
B34: Maintenance | C34: =Jan!C28 | D34: =Feb!C28 | E34: =Mar!C28 | F34: =Apr!C28 | G34: =May!C28 | H34: =Jun!C28 | I34: =Jul!C28 | J34: =Aug!C28 | K34: =Sep!C28 | L34: =Oct!C28 | M34: =Nov!C28 | N34: =Dec!C28 | O34: =SUM(C34:N34) | P34: =IF(ISERROR(O34/SUM($O$13:$O$37)),"%",O34/SUM($O$13:$O$37))
B35: Home Insurance | C35: =Jan!C29 | D35: =Feb!C29 | E35: =Mar!C29 | F35: =Apr!C29 | G35: =May!C29 | H35: =Jun!C29 | I35: =Jul!C29 | J35: =Aug!C29 | K35: =Sep!C29 | L35: =Oct!C29 | M35: =Nov!C29 | N35: =Dec!C29 | O35: =SUM(C35:N35) | P35: =IF(ISERROR(O35/SUM($O$13:$O$37)),"%",O35/SUM($O$13:$O$37))
B36: Car Loan Payment | C36: =Jan!C30 | D36: =Feb!C30 | E36: =Mar!C30 | F36: =Apr!C30 | G36: =May!C30 | H36: =Jun!C30 | I36: =Jul!C30 | J36: =Aug!C30 | K36: =Sep!C30 | L36: =Oct!C30 | M36: =Nov!C30 | N36: =Dec!C30 | O36: =SUM(C36:N36) | P36: =IF(ISERROR(O36/SUM($O$13:$O$37)),"%",O36/SUM($O$13:$O$37))
B37: Other | C37: =SUM(Jan!$J$37:$BS$40) | D37: =SUM(Feb!$J$37:$BS$40) | E37: =SUM(Mar!$J$37:$BS$40) | F37: =SUM(Apr!$J$37:$BS$40) | G37: =SUM(May!$J$37:$BS$40) | H37: =SUM(Jun!$J$37:$BS$40) | I37: =SUM(Jul!$J$37:$BS$40) | J37: =SUM(Aug!$J$37:$BS$40) | K37: =SUM(Sep!$J$37:$BS$40) | L37: =SUM(Oct!$J$37:$BS$40) | M37: =SUM(Nov!$J$37:$BS$40) | N37: =SUM(Dec!$J$37:$BS$40) | O37: =SUM(C37:N37) | P37: =IF(ISERROR(O37/SUM($O$13:$O$37)),"%",O37/SUM($O$13:$O$37))
B38: Total Expenses | C38: =SUM(C13:C37)-C24 | D38: =SUM(D13:D37)-D24 | E38: =SUM(E13:E37)-E24 | F38: =SUM(F13:F37)-F24 | G38: =SUM(G13:G37)-G24 | H38: =SUM(H13:H37)-H24 | I38: =SUM(I13:I37)-I24 | J38: =SUM(J13:J37)-J24 | ... O38: =SUM(O13:O37)-O24
B39: Net | C39: =C38+C24 | D39: =D38+D24 | E39: =E38+E24 | F39: =F38+F24 | G39: =G38+G24 | H39: =H38+H24 | I39: =I38+I24 | J39: =J38+J24 | ... O39: =O38+O24
B46: Book version | C46: v2.0

Sheet Jan
B1: =IF(OR(B2="",D2=""),"",DATE(B2,D2,1)) | C1: =IF(B1="","",DATE(YEAR(B1),MONTH(B1)+1,DAY(B1)-1))
B2: =IF('Annual Summary'!F5="","",'Annual Summary'!F5) | C2: / | D2: 1 | E2: Monthly Household Income & Expenses | I2: Daily Record | J2: =$B$1 | K2: =IF(J2="","",TEXT(J2,"ddd")) | L2: =IF(J2="","",IF(J2>=$C$1,"",J2+1)) | M2: =IF(L2="","",TEXT(L2,"ddd")) | N2: =IF(L2="","",IF(L2>=$C$1,"",L2+1)) | O2: =IF(N2="","",TEXT(N2,"ddd")) | P2: =IF(N2="","",IF(N2>=$C$1,"",N2+1)) | Q2: =IF(P2="","",TEXT(P2,"ddd")) | R2: =IF(P2="","",IF(P2>=$C$1,"",P2+1)) | S2: =IF(R2="","",TEXT(R2,"ddd")) | T2: =IF(R2="","",IF(R2>=$C$1,"",R2+1)) | U2: =IF(T2="","",TEXT(T2,"ddd")) | V2: =IF(T2="","",IF(T2>=$C$1,"",T2+1)) | W2: =IF(V2="","",TEXT(V2,"ddd")) | X2: =IF(V2="","",IF(V2>=$C$1,"",V2+1)) | Y2: =IF(X2="","",TEXT(X2,"ddd")) | Z2: =IF(X2="","",IF(X2>=$C$1,"",X2+1)) | AA2: =IF(Z2="","",TEXT(Z2,"ddd")) | AB2: =IF(Z2="","",IF(Z2>=$C$1,"",Z2+1)) | AC2: =IF(AB2="","",TEXT(AB2,"ddd")) | AD2: =IF(AB2="","",IF(AB2>=$C$1,"",AB2+1)) | AE2: =IF(AD2="","",TEXT(AD2,"ddd")) | AF2: =IF(AD2="","",IF(AD2>=$C$1,"",AD2+1)) | AG2: =IF(AF2="","",TEXT(AF2,"ddd")) | AH2: =IF(AF2="","",IF(AF2>=$C$1,"",AF2+1)) | AI2: =IF(AH2="","",TEXT(AH2,"ddd")) | AJ2: =IF(AH2="","",IF(AH2>=$C$1,"",AH2+1)) | AK2: =IF(AJ2="","",TEXT(AJ2,"ddd")) | AL2: =IF(AJ2="","",IF(AJ2>=$C$1,"",AJ2+1)) | AM2: =IF(AL2="","",TEXT(AL2,"ddd")) | AN2: =IF(AL2="","",IF(AL2>=$C$1,"",AL2+1)) | AO2: =IF(AN2="","",TEXT(AN2,"ddd")) | AP2: =IF(AN2="","",IF(AN2>=$C$1,"",AN2+1)) | AQ2: =IF(AP2="","",TEXT(AP2,"ddd")) | AR2: =IF(AP2="","",IF(AP2>=$C$1,"",AP2+1)) | AS2: =IF(AR2="","",TEXT(AR2,"ddd")) | AT2: =IF(AR2="","",IF(AR2>=$C$1,"",AR2+1)) | AU2: =IF(AT2="","",TEXT(AT2,"ddd")) | AV2: =IF(AT2="","",IF(AT2>=$C$1,"",AT2+1)) | AW2: =IF(AV2="","",TEXT(AV2,"ddd")) | AX2: =IF(AV2="","",IF(AV2>=$C$1,"",AV2+1)) | AY2: =IF(AX2="","",TEXT(AX2,"ddd")) | AZ2: =IF(AX2="","",IF(AX2>=$C$1,"",AX2+1)) | BA2: =IF(AZ2="","",TEXT(AZ2,"ddd")) | BB2: =IF(AZ2="","",IF(AZ2>=$C$1,"",AZ2+1)) | BC2: =IF(BB2="","",TEXT(BB2,"ddd")) | BD2: =IF(BB2="","",IF(BB2>=$C$1,"",BB2+1)) | BE2: =IF(BD2="","",TEXT(BD2,"ddd")) | BF2: =IF(BD2="","",IF(BD2>=$C$1,"",BD2+1)) | BG2: =IF(BF2="","",TEXT(BF2,"ddd")) | BH2: =IF(BF2="","",IF(BF2>=$C$1,"",BF2+1)) | BI2: =IF(BH2="","",TEXT(BH2,"ddd")) | BJ2: =IF(BH2="","",IF(BH2>=$C$1,"",BH2+1)) | BK2: =IF(BJ2="","",TEXT(BJ2,"ddd")) | BL2: =IF(BJ2="","",IF(BJ2>=$C$1,"",BJ2+1)) | BM2: =IF(BL2="","",TEXT(BL2,"ddd")) | BN2: =IF(BL2="","",IF(BL2>=$C$1,"",BL2+1)) | BO2: =IF(BN2="","",TEXT(BN2,"ddd")) | BP2: =IF(BN2="","",IF(BN2>=$C$1,"",BN2+1)) | BQ2: =IF(BP2="","",TEXT(BP2,"ddd")) | BR2: =IF(BP2="","",IF(BP2>=$C$1,"",BP2+1)) | BS2: =IF(BR2="","",TEXT(BR2,"ddd"))
I3: Holiday | J3: =IF(ISNA(VLOOKUP(J$2,Holidays!$B$5:$C$33,2,FALSE)),"",VLOOKUP(J$2,Holidays!$B$5:$C$33,2,FALSE)) | L3: =IF(ISNA(VLOOKUP(L$2,Holidays!$B$5:$C$33,2,FALSE)),"",VLOOKUP(L$2,Holidays!$B$5:$C$33,2,FALSE)) | N3: =IF(ISNA(VLOOKUP(N$2,Holidays!$B$5:$C$33,2,FALSE)),"",VLOOKUP(N$2,Holidays!$B$5:$C$33,2,FALSE)) | P3: =IF(ISNA(VLOOKUP(P$2,Holidays!$B$5:$C$33,2,FALSE)),"",VLOOKUP(P$2,Holidays!$B$5:$C$33,2,FALSE)) | R3: =IF(ISNA(VLOOKUP(R$2,Holidays!$B$5:$C$33,2,FALSE)),"",VLOOKUP(R$2,Holidays!$B$5:$C$33,2,FALSE)) | T3: =IF(ISNA(VLOOKUP(T$2,Holidays!$B$5:$C$33,2,FALSE)),"",VLOOKUP(T$2,Holidays!$B$5:$C$33,2,FALSE)) | V3: =IF(ISNA(VLOOKUP(V$2,Holidays!$B$5:$C$33,2,FALSE)),"",VLOOKUP(V$2,Holidays!$B$5:$C$33,2,FALSE)) | X3: =IF(ISNA(VLOOKUP(X$2,Holidays!$B$5:$C$33,2,FALSE)),"",VLOOKUP(X$2,Holidays!$B$5:$C$33,2,FALSE)) | Z3: =IF(ISNA(VLOOKUP(Z$2,Holidays!$B$5:$C$33,2,FALSE)),"",VLOOKUP(Z$2,Holidays!$B$5:$C$33,2,FALSE)) | AB3: =IF(ISNA(VLOOKUP(AB$2,Holidays!$B$5:$C$33,2,FALSE)),"",VLOOKUP(AB$2,Holidays!$B$5:$C$33,2,FALSE)) | AD3: =IF(ISNA(VLOOKUP(AD$2,Holidays!$B$5:$C$33,2,FALSE)),"",VLOOKUP(AD$2,Holidays!$B$5:$C$33,2,FALSE)) | AF3: =IF(ISNA(VLOOKUP(AF$2,Holidays!$B$5:$C$33,2,FALSE)),"",VLOOKUP(AF$2,Holidays!$B$5:$C$33,2,FALSE)) | AH3: =IF(ISNA(VLOOKUP(AH$2,Holidays!$B$5:$C$33,2,FALSE)),"",VLOOKUP(AH$2,Holidays!$B$5:$C$33,2,FALSE)) | AJ3: =IF(ISNA(VLOOKUP(AJ$2,Holidays!$B$5:$C$33,2,FALSE)),"",VLOOKUP(AJ$2,Holidays!$B$5:$C$33,2,FALSE)) | AL3: =IF(ISNA(VLOOKUP(AL$2,Holidays!$B$5:$C$33,2,FALSE)),"",VLOOKUP(AL$2,Holidays!$B$5:$C$33,2,FALSE)) | AN3: =IF(ISNA(VLOOKUP(AN$2,Holidays!$B$5:$C$33,2,FALSE)),"",VLOOKUP(AN$2,Holidays!$B$5:$C$33,2,FALSE)) | AP3: =IF(ISNA(VLOOKUP(AP$2,Holidays!$B$5:$C$33,2,FALSE)),"",VLOOKUP(AP$2,Holidays!$B$5:$C$33,2,FALSE)) | AR3: =IF(ISNA(VLOOKUP(AR$2,Holidays!$B$5:$C$33,2,FALSE)),"",VLOOKUP(AR$2,Holidays!$B$5:$C$33,2,FALSE)) | AT3: =IF(ISNA(VLOOKUP(AT$2,Holidays!$B$5:$C$33,2,FALSE)),"",VLOOKUP(AT$2,Holidays!$B$5:$C$33,2,FALSE)) | AV3: =IF(ISNA(VLOOKUP(AV$2,Holidays!$B$5:$C$33,2,FALSE)),"",VLOOKUP(AV$2,Holidays!$B$5:$C$33,2,FALSE)) | AX3: =IF(ISNA(VLOOKUP(AX$2,Holidays!$B$5:$C$33,2,FALSE)),"",VLOOKUP(AX$2,Holidays!$B$5:$C$33,2,FALSE)) | AZ3: =IF(ISNA(VLOOKUP(AZ$2,Holidays!$B$5:$C$33,2,FALSE)),"",VLOOKUP(AZ$2,Holidays!$B$5:$C$33,2,FALSE)) | BB3: =IF(ISNA(VLOOKUP(BB$2,Holidays!$B$5:$C$33,2,FALSE)),"",VLOOKUP(BB$2,Holidays!$B$5:$C$33,2,FALSE)) | BD3: =IF(ISNA(VLOOKUP(BD$2,Holidays!$B$5:$C$33,2,FALSE)),"",VLOOKUP(BD$2,Holidays!$B$5:$C$33,2,FALSE)) | BF3: =IF(ISNA(VLOOKUP(BF$2,Holidays!$B$5:$C$33,2,FALSE)),"",VLOOKUP(BF$2,Holidays!$B$5:$C$33,2,FALSE)) | BH3: =IF(ISNA(VLOOKUP(BH$2,Holidays!$B$5:$C$33,2,FALSE)),"",VLOOKUP(BH$2,Holidays!$B$5:$C$33,2,FALSE)) | BJ3: =IF(ISNA(VLOOKUP(BJ$2,Holidays!$B$5:$C$33,2,FALSE)),"",VLOOKUP(BJ$2,Holidays!$B$5:$C$33,2,FALSE)) | BL3: =IF(ISNA(VLOOKUP(BL$2,Holidays!$B$5:$C$33,2,FALSE)),"",VLOOKUP(BL$2,Holidays!$B$5:$C$33,2,FALSE)) | BN3: =IF(ISNA(VLOOKUP(BN$2,Holidays!$B$5:$C$33,2,FALSE)),"",VLOOKUP(BN$2,Holidays!$B$5:$C$33,2,FALSE)) | BP3: =IF(ISNA(VLOOKUP(BP$2,Holidays!$B$5:$C$33,2,FALSE)),"",VLOOKUP(BP$2,Holidays!$B$5:$C$33,2,FALSE)) | BR3: =IF(ISNA(VLOOKUP(BR$2,Holidays!$B$5:$C$33,2,FALSE)),"",VLOOKUP(BR$2,Holidays!$B$5:$C$33,2,FALSE))
F4: Back to Annual Summary | I4: Anniversary | J4: =IF(ISNA(VLOOKUP(J$2,Holidays!$F$5:$G$33,2,FALSE)),"",VLOOKUP(J$2,Holidays!$F$5:$G$33,2,FALSE)) | L4: =IF(ISNA(VLOOKUP(L$2,Holidays!$F$5:$G$33,2,FALSE)),"",VLOOKUP(L$2,Holidays!$F$5:$G$33,2,FALSE)) | N4: =IF(ISNA(VLOOKUP(N$2,Holidays!$F$5:$G$33,2,FALSE)),"",VLOOKUP(N$2,Holidays!$F$5:$G$33,2,FALSE)) | P4: =IF(ISNA(VLOOKUP(P$2,Holidays!$F$5:$G$33,2,FALSE)),"",VLOOKUP(P$2,Holidays!$F$5:$G$33,2,FALSE)) | R4: =IF(ISNA(VLOOKUP(R$2,Holidays!$F$5:$G$33,2,FALSE)),"",VLOOKUP(R$2,Holidays!$F$5:$G$33,2,FALSE)) | T4: =IF(ISNA(VLOOKUP(T$2,Holidays!$F$5:$G$33,2,FALSE)),"",VLOOKUP(T$2,Holidays!$F$5:$G$33,2,FALSE)) | V4: =IF(ISNA(VLOOKUP(V$2,Holidays!$F$5:$G$33,2,FALSE)),"",VLOOKUP(V$2,Holidays!$F$5:$G$33,2,FALSE)) | X4: =IF(ISNA(VLOOKUP(X$2,Holidays!$F$5:$G$33,2,FALSE)),"",VLOOKUP(X$2,Holidays!$F$5:$G$33,2,FALSE)) | Z4: =IF(ISNA(VLOOKUP(Z$2,Holidays!$F$5:$G$33,2,FALSE)),"",VLOOKUP(Z$2,Holidays!$F$5:$G$33,2,FALSE)) | AB4: =IF(ISNA(VLOOKUP(AB$2,Holidays!$F$5:$G$33,2,FALSE)),"",VLOOKUP(AB$2,Holidays!$F$5:$G$33,2,FALSE)) | AD4: =IF(ISNA(VLOOKUP(AD$2,Holidays!$F$5:$G$33,2,FALSE)),"",VLOOKUP(AD$2,Holidays!$F$5:$G$33,2,FALSE)) | AF4: =IF(ISNA(VLOOKUP(AF$2,Holidays!$F$5:$G$33,2,FALSE)),"",VLOOKUP(AF$2,Holidays!$F$5:$G$33,2,FALSE)) | AH4: =IF(ISNA(VLOOKUP(AH$2,Holidays!$F$5:$G$33,2,FALSE)),"",VLOOKUP(AH$2,Holidays!$F$5:$G$33,2,FALSE)) | AJ4: =IF(ISNA(VLOOKUP(AJ$2,Holidays!$F$5:$G$33,2,FALSE)),"",VLOOKUP(AJ$2,Holidays!$F$5:$G$33,2,FALSE)) | AL4: =IF(ISNA(VLOOKUP(AL$2,Holidays!$F$5:$G$33,2,FALSE)),"",VLOOKUP(AL$2,Holidays!$F$5:$G$33,2,FALSE)) | AN4: =IF(ISNA(VLOOKUP(AN$2,Holidays!$F$5:$G$33,2,FALSE)),"",VLOOKUP(AN$2,Holidays!$F$5:$G$33,2,FALSE)) | AP4: =IF(ISNA(VLOOKUP(AP$2,Holidays!$F$5:$G$33,2,FALSE)),"",VLOOKUP(AP$2,Holidays!$F$5:$G$33,2,FALSE)) | AR4: =IF(ISNA(VLOOKUP(AR$2,Holidays!$F$5:$G$33,2,FALSE)),"",VLOOKUP(AR$2,Holidays!$F$5:$G$33,2,FALSE)) | AT4: =IF(ISNA(VLOOKUP(AT$2,Holidays!$F$5:$G$33,2,FALSE)),"",VLOOKUP(AT$2,Holidays!$F$5:$G$33,2,FALSE)) | AV4: =IF(ISNA(VLOOKUP(AV$2,Holidays!$F$5:$G$33,2,FALSE)),"",VLOOKUP(AV$2,Holidays!$F$5:$G$33,2,FALSE)) | AX4: =IF(ISNA(VLOOKUP(AX$2,Holidays!$F$5:$G$33,2,FALSE)),"",VLOOKUP(AX$2,Holidays!$F$5:$G$33,2,FALSE)) | AZ4: =IF(ISNA(VLOOKUP(AZ$2,Holidays!$F$5:$G$33,2,FALSE)),"",VLOOKUP(AZ$2,Holidays!$F$5:$G$33,2,FALSE)) | BB4: =IF(ISNA(VLOOKUP(BB$2,Holidays!$F$5:$G$33,2,FALSE)),"",VLOOKUP(BB$2,Holidays!$F$5:$G$33,2,FALSE)) | BD4: =IF(ISNA(VLOOKUP(BD$2,Holidays!$F$5:$G$33,2,FALSE)),"",VLOOKUP(BD$2,Holidays!$F$5:$G$33,2,FALSE)) | BF4: =IF(ISNA(VLOOKUP(BF$2,Holidays!$F$5:$G$33,2,FALSE)),"",VLOOKUP(BF$2,Holidays!$F$5:$G$33,2,FALSE)) | BH4: =IF(ISNA(VLOOKUP(BH$2,Holidays!$F$5:$G$33,2,FALSE)),"",VLOOKUP(BH$2,Holidays!$F$5:$G$33,2,FALSE)) | BJ4: =IF(ISNA(VLOOKUP(BJ$2,Holidays!$F$5:$G$33,2,FALSE)),"",VLOOKUP(BJ$2,Holidays!$F$5:$G$33,2,FALSE)) | BL4: =IF(ISNA(VLOOKUP(BL$2,Holidays!$F$5:$G$33,2,FALSE)),"",VLOOKUP(BL$2,Holidays!$F$5:$G$33,2,FALSE)) | BN4: =IF(ISNA(VLOOKUP(BN$2,Holidays!$F$5:$G$33,2,FALSE)),"",VLOOKUP(BN$2,Holidays!$F$5:$G$33,2,FALSE)) | BP4: =IF(ISNA(VLOOKUP(BP$2,Holidays!$F$5:$G$33,2,FALSE)),"",VLOOKUP(BP$2,Holidays!$F$5:$G$33,2,FALSE)) | BR4: =IF(ISNA(VLOOKUP(BR$2,Holidays!$F$5:$G$33,2,FALSE)),"",VLOOKUP(BR$2,Holidays!$F$5:$G$33,2,FALSE))
J5: Item | K5: Amount | L5: Item | M5: Amount | N5: Item | O5: Amount | P5: Item | Q5: Amount | R5: Item | S5: Amount | T5: Item | U5: Amount | V5: Item | W5: Amount | X5: Item | Y5: Amount | Z5: Item | AA5: Amount | AB5: Item | AC5: Amount | AD5: Item | AE5: Amount | AF5: Item | AG5: Amount | AH5: Item | AI5: Amount | AJ5: Item | AK5: Amount | AL5: Item | AM5: Amount | AN5: Item | AO5: Amount | AP5: Item | AQ5: Amount | AR5: Item | AS5: Amount | AT5: Item | AU5: Amount | AV5: Item | AW5: Amount | AX5: Item | AY5: Amount | AZ5: Item | BA5: Amount | BB5: Item | BC5: Amount | BD5: Item | BE5: Amount | BF5: Item | BG5: Amount | BH5: Item | BI5: Amount | BJ5: Item | BK5: Amount | BL5: Item | BM5: Amount | BN5: Item | BO5: Amount | BP5: Item | BQ5: Amount | BR5: Item | BS5: Amount
B6: Income This Month | F6: Living Expenses This Month | I6: Meals
B7: Item | C7: Amount | D7: Date Received | F7: Item | G7: Amount Spent
F8: Food (Meals) | G8: =SUM(J21:BS21)
F9: Household Goods Total | G9: =SUM(J22:BS27)
F10: Education & Enrichment | G10: =SUM(J28:BS28)
F11: All Other Items Total | G11: =SUM(J30:BS41)
B12: Total Income | C12: =SUM(C8:C11) | F12: Total Living Expenses | G12: =SUM(G8:G11)+SUM(J29:BS29)
B16: Fixed Expenses This Month
B17: Item | C17: Amount | D17: Date Paid | F17: Balance This Month | I17: Snacks
B18: Income offset | F18: =C12-C39-G12+SUM(J43:BS43)
B19: GAS
B20: Electricity & Water | I20: Dining Out
B21: RESP | F21: Cumulative Balance | I21: Total Food | K21: =SUM(K6:K20) | L21: =SUM(L6:L20) | M21: =SUM(M6:M20) | N21: =SUM(N6:N20) | O21: =SUM(O6:O20) | P21: =SUM(P6:P20) | Q21: =SUM(Q6:Q20) | R21: =SUM(R6:R20) | ... BS21: =SUM(BS6:BS20)
B22: Mobile Phone | F22: =F18 | I22: Household Goods
B23: Daycare
B24: Rent / Mortgage
B25: Internet | F25: Notes This Month
B26: Car Insurance
B27: Property Tax
B28: Fuel / Maintenance | I28: Education & Enrichment
B29: Home Insurance | I29: Fuel
B30: Car Loan Payment | I30: Clothing
B31: Housing Management Fee
B32: Term Deposit | I32: Medical
B33: Pocket Money | I33: Hair & Cosmetics
B34: Savings | I34: Transportation
I35: Entertainment
I36: Gifts & Social
I37: Other
B39: Total Fixed Expenses | C39: =SUM(C18:C38)
I42: Daily Expenses Total | K42: =SUM(K21:K41) | M42: =SUM(M21:M41) | O42: =SUM(O21:O41) | Q42: =SUM(Q21:Q41) | S42: =SUM(S21:S41) | U42: =SUM(U21:U41) | W42: =SUM(W21:W41) | Y42: =SUM(Y21:Y41) | AA42: =SUM(AA21:AA41) | AC42: =SUM(AC21:AC41) | AE42: =SUM(AE21:AE41) | AG42: =SUM(AG21:AG41) | AI42: =SUM(AI21:AI41) | AK42: =SUM(AK21:AK41) | AM42: =SUM(AM21:AM41) | AO42: =SUM(AO21:AO41) | AQ42: =SUM(AQ21:AQ41) | AS42: =SUM(AS21:AS41) | AU42: =SUM(AU21:AU41) | AW42: =SUM(AW21:AW41) | AY42: =SUM(AY21:AY41) | BA42: =SUM(BA21:BA41) | BC42: =SUM(BC21:BC41) | BE42: =SUM(BE21:BE41) | BG42: =SUM(BG21:BG41) | BI42: =SUM(BI21:BI41) | BK42: =SUM(BK21:BK41) | BM42: =SUM(BM21:BM41) | BO42: =SUM(BO21:BO41) | BQ42: =SUM(BQ21:BQ41) | BS42: =SUM(BS21:BS41)
I43: Temporary Income
I44: Balance | K44: =$C$12-$C$39-K42+K43 | M44: =+K44-M42+M43 | O44: =+M44-O42+O43 | Q44: =+O44-Q42+Q43 | S44: =+Q44-S42+S43 | U44: =+S44-U42+U43 | W44: =+U44-W42+W43 | Y44: =+W44-Y42+Y43 | AA44: =+Y44-AA42+AA43 | AC44: =+AA44-AC42+AC43 | AE44: =+AC44-AE42+AE43 | AG44: =+AE44-AG42+AG43 | AI44: =+AG44-AI42+AI43 | AK44: =+AI44-AK42+AK43 | AM44: =+AK44-AM42+AM43 | AO44: =+AM44-AO42+AO43 | AQ44: =+AO44-AQ42+AQ43 | AS44: =+AQ44-AS42+AS43 | AU44: =+AS44-AU42+AU43 | AW44: =+AU44-AW42+AW43 | AY44: =+AW44-AY42+AY43 | BA44: =+AY44-BA42+BA43 | BC44: =+BA44-BC42+BC43 | BE44: =+BC44-BE42+BE43 | BG44: =+BE44-BG42+BG43 | BI44: =+BG44-BI42+BI43 | BK44: =+BI44-BK42+BK43 | BM44: =+BK44-BM42+BM43 | BO44: =+BM44-BO42+BO43 | BQ44: =+BO44-BQ42+BQ43 | BS44: =+BQ44-BS42+BS43
B47: Transactions this month One row per posted line. These rows are not included in the totals above. Payments are not listed.
B48: Card | C48: Trans date | D48: Post date | F48: Description | G48: Amount | I48: Category | J48: Receipt # | CA48: Txn key | CB48: Statement file | CC48: FX note | CD48: Status | CE48: Where written | CF48: Issuer category | CG48: Linked key
...

Sheet Feb
B1: =IF(OR(B2="",D2=""),"",DATE(B2,D2,1)) | C1: =IF(B1="","",DATE(YEAR(B1),MONTH(B1)+1,DAY(B1)-1))
B2: =IF('Annual Summary'!F5="","",'Annual Summary'!F5) | C2: / | D2: 2 | E2: Monthly Household Income & Expenses | I2: Daily Record | J2: =$B$1 | K2: =IF(J2="","",TEXT(J2,"ddd")) | L2: =IF(J2="","",IF(J2>=$C$1,"",J2+1)) | M2: =IF(L2="","",TEXT(L2,"ddd")) | N2: =IF(L2="","",IF(L2>=$C$1,"",L2+1)) | O2: =IF(N2="","",TEXT(N2,"ddd")) | P2: =IF(N2="","",IF(N2>=$C$1,"",N2+1)) | Q2: =IF(P2="","",TEXT(P2,"ddd")) | R2: =IF(P2="","",IF(P2>=$C$1,"",P2+1)) | S2: =IF(R2="","",TEXT(R2,"ddd")) | T2: =IF(R2="","",IF(R2>=$C$1,"",R2+1)) | U2: =IF(T2="","",TEXT(T2,"ddd")) | V2: =IF(T2="","",IF(T2>=$C$1,"",T2+1)) | W2: =IF(V2="","",TEXT(V2,"ddd")) | X2: =IF(V2="","",IF(V2>=$C$1,"",V2+1)) | Y2: =IF(X2="","",TEXT(X2,"ddd")) | Z2: =IF(X2="","",IF(X2>=$C$1,"",X2+1)) | AA2: =IF(Z2="","",TEXT(Z2,"ddd")) | AB2: =IF(Z2="","",IF(Z2>=$C$1,"",Z2+1)) | AC2: =IF(AB2="","",TEXT(AB2,"ddd")) | AD2: =IF(AB2="","",IF(AB2>=$C$1,"",AB2+1)) | AE2: =IF(AD2="","",TEXT(AD2,"ddd")) | AF2: =IF(AD2="","",IF(AD2>=$C$1,"",AD2+1)) | AG2: =IF(AF2="","",TEXT(AF2,"ddd")) | AH2: =IF(AF2="","",IF(AF2>=$C$1,"",AF2+1)) | AI2: =IF(AH2="","",TEXT(AH2,"ddd")) | AJ2: =IF(AH2="","",IF(AH2>=$C$1,"",AH2+1)) | AK2: =IF(AJ2="","",TEXT(AJ2,"ddd")) | AL2: =IF(AJ2="","",IF(AJ2>=$C$1,"",AJ2+1)) | AM2: =IF(AL2="","",TEXT(AL2,"ddd")) | AN2: =IF(AL2="","",IF(AL2>=$C$1,"",AL2+1)) | AO2: =IF(AN2="","",TEXT(AN2,"ddd")) | AP2: =IF(AN2="","",IF(AN2>=$C$1,"",AN2+1)) | AQ2: =IF(AP2="","",TEXT(AP2,"ddd")) | AR2: =IF(AP2="","",IF(AP2>=$C$1,"",AP2+1)) | AS2: =IF(AR2="","",TEXT(AR2,"ddd")) | AT2: =IF(AR2="","",IF(AR2>=$C$1,"",AR2+1)) | AU2: =IF(AT2="","",TEXT(AT2,"ddd")) | AV2: =IF(AT2="","",IF(AT2>=$C$1,"",AT2+1)) | AW2: =IF(AV2="","",TEXT(AV2,"ddd")) | AX2: =IF(AV2="","",IF(AV2>=$C$1,"",AV2+1)) | AY2: =IF(AX2="","",TEXT(AX2,"ddd")) | AZ2: =IF(AX2="","",IF(AX2>=$C$1,"",AX2+1)) | BA2: =IF(AZ2="","",TEXT(AZ2,"ddd")) | BB2: =IF(AZ2="","",IF(AZ2>=$C$1,"",AZ2+1)) | BC2: =IF(BB2="","",TEXT(BB2,"ddd")) | BD2: =IF(BB2="","",IF(BB2>=$C$1,"",BB2+1)) | BE2: =IF(BD2="","",TEXT(BD2,"ddd")) | BF2: =IF(BD2="","",IF(BD2>=$C$1,"",BD2+1)) | BG2: =IF(BF2="","",TEXT(BF2,"ddd")) | BH2: =IF(BF2="","",IF(BF2>=$C$1,"",BF2+1)) | BI2: =IF(BH2="","",TEXT(BH2,"ddd")) | BJ2: =IF(BH2="","",IF(BH2>=$C$1,"",BH2+1)) | BK2: =IF(BJ2="","",TEXT(BJ2,"ddd")) | BL2: =IF(BJ2="","",IF(BJ2>=$C$1,"",BJ2+1)) | BM2: =IF(BL2="","",TEXT(BL2,"ddd")) | BN2: =IF(BL2="","",IF(BL2>=$C$1,"",BL2+1)) | BO2: =IF(BN2="","",TEXT(BN2,"ddd"))
I3: Holiday | J3: =IF(ISNA(VLOOKUP(J$2,Holidays!$B$5:$C$33,2,FALSE)),"",VLOOKUP(J$2,Holidays!$B$5:$C$33,2,FALSE)) | L3: =IF(ISNA(VLOOKUP(L$2,Holidays!$B$5:$C$33,2,FALSE)),"",VLOOKUP(L$2,Holidays!$B$5:$C$33,2,FALSE)) | N3: =IF(ISNA(VLOOKUP(N$2,Holidays!$B$5:$C$33,2,FALSE)),"",VLOOKUP(N$2,Holidays!$B$5:$C$33,2,FALSE)) | P3: =IF(ISNA(VLOOKUP(P$2,Holidays!$B$5:$C$33,2,FALSE)),"",VLOOKUP(P$2,Holidays!$B$5:$C$33,2,FALSE)) | R3: =IF(ISNA(VLOOKUP(R$2,Holidays!$B$5:$C$33,2,FALSE)),"",VLOOKUP(R$2,Holidays!$B$5:$C$33,2,FALSE)) | T3: =IF(ISNA(VLOOKUP(T$2,Holidays!$B$5:$C$33,2,FALSE)),"",VLOOKUP(T$2,Holidays!$B$5:$C$33,2,FALSE)) | V3: =IF(ISNA(VLOOKUP(V$2,Holidays!$B$5:$C$33,2,FALSE)),"",VLOOKUP(V$2,Holidays!$B$5:$C$33,2,FALSE)) | X3: =IF(ISNA(VLOOKUP(X$2,Holidays!$B$5:$C$33,2,FALSE)),"",VLOOKUP(X$2,Holidays!$B$5:$C$33,2,FALSE)) | Z3: =IF(ISNA(VLOOKUP(Z$2,Holidays!$B$5:$C$33,2,FALSE)),"",VLOOKUP(Z$2,Holidays!$B$5:$C$33,2,FALSE)) | AB3: =IF(ISNA(VLOOKUP(AB$2,Holidays!$B$5:$C$33,2,FALSE)),"",VLOOKUP(AB$2,Holidays!$B$5:$C$33,2,FALSE)) | AD3: =IF(ISNA(VLOOKUP(AD$2,Holidays!$B$5:$C$33,2,FALSE)),"",VLOOKUP(AD$2,Holidays!$B$5:$C$33,2,FALSE)) | AF3: =IF(ISNA(VLOOKUP(AF$2,Holidays!$B$5:$C$33,2,FALSE)),"",VLOOKUP(AF$2,Holidays!$B$5:$C$33,2,FALSE)) | AH3: =IF(ISNA(VLOOKUP(AH$2,Holidays!$B$5:$C$33,2,FALSE)),"",VLOOKUP(AH$2,Holidays!$B$5:$C$33,2,FALSE)) | AJ3: =IF(ISNA(VLOOKUP(AJ$2,Holidays!$B$5:$C$33,2,FALSE)),"",VLOOKUP(AJ$2,Holidays!$B$5:$C$33,2,FALSE)) | AL3: =IF(ISNA(VLOOKUP(AL$2,Holidays!$B$5:$C$33,2,FALSE)),"",VLOOKUP(AL$2,Holidays!$B$5:$C$33,2,FALSE)) | AN3: =IF(ISNA(VLOOKUP(AN$2,Holidays!$B$5:$C$33,2,FALSE)),"",VLOOKUP(AN$2,Holidays!$B$5:$C$33,2,FALSE)) | AP3: =IF(ISNA(VLOOKUP(AP$2,Holidays!$B$5:$C$33,2,FALSE)),"",VLOOKUP(AP$2,Holidays!$B$5:$C$33,2,FALSE)) | AR3: =IF(ISNA(VLOOKUP(AR$2,Holidays!$B$5:$C$33,2,FALSE)),"",VLOOKUP(AR$2,Holidays!$B$5:$C$33,2,FALSE)) | AT3: =IF(ISNA(VLOOKUP(AT$2,Holidays!$B$5:$C$33,2,FALSE)),"",VLOOKUP(AT$2,Holidays!$B$5:$C$33,2,FALSE)) | AV3: =IF(ISNA(VLOOKUP(AV$2,Holidays!$B$5:$C$33,2,FALSE)),"",VLOOKUP(AV$2,Holidays!$B$5:$C$33,2,FALSE)) | AX3: =IF(ISNA(VLOOKUP(AX$2,Holidays!$B$5:$C$33,2,FALSE)),"",VLOOKUP(AX$2,Holidays!$B$5:$C$33,2,FALSE)) | AZ3: =IF(ISNA(VLOOKUP(AZ$2,Holidays!$B$5:$C$33,2,FALSE)),"",VLOOKUP(AZ$2,Holidays!$B$5:$C$33,2,FALSE)) | BB3: =IF(ISNA(VLOOKUP(BB$2,Holidays!$B$5:$C$33,2,FALSE)),"",VLOOKUP(BB$2,Holidays!$B$5:$C$33,2,FALSE)) | BD3: =IF(ISNA(VLOOKUP(BD$2,Holidays!$B$5:$C$33,2,FALSE)),"",VLOOKUP(BD$2,Holidays!$B$5:$C$33,2,FALSE)) | BF3: =IF(ISNA(VLOOKUP(BF$2,Holidays!$B$5:$C$33,2,FALSE)),"",VLOOKUP(BF$2,Holidays!$B$5:$C$33,2,FALSE)) | BH3: =IF(ISNA(VLOOKUP(BH$2,Holidays!$B$5:$C$33,2,FALSE)),"",VLOOKUP(BH$2,Holidays!$B$5:$C$33,2,FALSE)) | BJ3: =IF(ISNA(VLOOKUP(BJ$2,Holidays!$B$5:$C$33,2,FALSE)),"",VLOOKUP(BJ$2,Holidays!$B$5:$C$33,2,FALSE)) | BL3: =IF(ISNA(VLOOKUP(BL$2,Holidays!$B$5:$C$33,2,FALSE)),"",VLOOKUP(BL$2,Holidays!$B$5:$C$33,2,FALSE)) | BN3: =IF(ISNA(VLOOKUP(BN$2,Holidays!$B$5:$C$33,2,FALSE)),"",VLOOKUP(BN$2,Holidays!$B$5:$C$33,2,FALSE)) | BP3: =IF(ISNA(VLOOKUP(BP$2,Holidays!$B$5:$C$33,2,FALSE)),"",VLOOKUP(BP$2,Holidays!$B$5:$C$33,2,FALSE)) | BR3: =IF(ISNA(VLOOKUP(BR$2,Holidays!$B$5:$C$33,2,FALSE)),"",VLOOKUP(BR$2,Holidays!$B$5:$C$33,2,FALSE))
F4: Back to Annual Summary | I4: Anniversary | J4: =IF(ISNA(VLOOKUP(J$2,Holidays!$F$5:$G$33,2,FALSE)),"",VLOOKUP(J$2,Holidays!$F$5:$G$33,2,FALSE)) | L4: =IF(ISNA(VLOOKUP(L$2,Holidays!$F$5:$G$33,2,FALSE)),"",VLOOKUP(L$2,Holidays!$F$5:$G$33,2,FALSE)) | N4: =IF(ISNA(VLOOKUP(N$2,Holidays!$F$5:$G$33,2,FALSE)),"",VLOOKUP(N$2,Holidays!$F$5:$G$33,2,FALSE)) | P4: =IF(ISNA(VLOOKUP(P$2,Holidays!$F$5:$G$33,2,FALSE)),"",VLOOKUP(P$2,Holidays!$F$5:$G$33,2,FALSE)) | R4: =IF(ISNA(VLOOKUP(R$2,Holidays!$F$5:$G$33,2,FALSE)),"",VLOOKUP(R$2,Holidays!$F$5:$G$33,2,FALSE)) | T4: =IF(ISNA(VLOOKUP(T$2,Holidays!$F$5:$G$33,2,FALSE)),"",VLOOKUP(T$2,Holidays!$F$5:$G$33,2,FALSE)) | V4: =IF(ISNA(VLOOKUP(V$2,Holidays!$F$5:$G$33,2,FALSE)),"",VLOOKUP(V$2,Holidays!$F$5:$G$33,2,FALSE)) | X4: =IF(ISNA(VLOOKUP(X$2,Holidays!$F$5:$G$33,2,FALSE)),"",VLOOKUP(X$2,Holidays!$F$5:$G$33,2,FALSE)) | Z4: =IF(ISNA(VLOOKUP(Z$2,Holidays!$F$5:$G$33,2,FALSE)),"",VLOOKUP(Z$2,Holidays!$F$5:$G$33,2,FALSE)) | AB4: =IF(ISNA(VLOOKUP(AB$2,Holidays!$F$5:$G$33,2,FALSE)),"",VLOOKUP(AB$2,Holidays!$F$5:$G$33,2,FALSE)) | AD4: =IF(ISNA(VLOOKUP(AD$2,Holidays!$F$5:$G$33,2,FALSE)),"",VLOOKUP(AD$2,Holidays!$F$5:$G$33,2,FALSE)) | AF4: =IF(ISNA(VLOOKUP(AF$2,Holidays!$F$5:$G$33,2,FALSE)),"",VLOOKUP(AF$2,Holidays!$F$5:$G$33,2,FALSE)) | AH4: =IF(ISNA(VLOOKUP(AH$2,Holidays!$F$5:$G$33,2,FALSE)),"",VLOOKUP(AH$2,Holidays!$F$5:$G$33,2,FALSE)) | AJ4: =IF(ISNA(VLOOKUP(AJ$2,Holidays!$F$5:$G$33,2,FALSE)),"",VLOOKUP(AJ$2,Holidays!$F$5:$G$33,2,FALSE)) | AL4: =IF(ISNA(VLOOKUP(AL$2,Holidays!$F$5:$G$33,2,FALSE)),"",VLOOKUP(AL$2,Holidays!$F$5:$G$33,2,FALSE)) | AN4: =IF(ISNA(VLOOKUP(AN$2,Holidays!$F$5:$G$33,2,FALSE)),"",VLOOKUP(AN$2,Holidays!$F$5:$G$33,2,FALSE)) | AP4: =IF(ISNA(VLOOKUP(AP$2,Holidays!$F$5:$G$33,2,FALSE)),"",VLOOKUP(AP$2,Holidays!$F$5:$G$33,2,FALSE)) | AR4: =IF(ISNA(VLOOKUP(AR$2,Holidays!$F$5:$G$33,2,FALSE)),"",VLOOKUP(AR$2,Holidays!$F$5:$G$33,2,FALSE)) | AT4: =IF(ISNA(VLOOKUP(AT$2,Holidays!$F$5:$G$33,2,FALSE)),"",VLOOKUP(AT$2,Holidays!$F$5:$G$33,2,FALSE)) | AV4: =IF(ISNA(VLOOKUP(AV$2,Holidays!$F$5:$G$33,2,FALSE)),"",VLOOKUP(AV$2,Holidays!$F$5:$G$33,2,FALSE)) | AX4: =IF(ISNA(VLOOKUP(AX$2,Holidays!$F$5:$G$33,2,FALSE)),"",VLOOKUP(AX$2,Holidays!$F$5:$G$33,2,FALSE)) | AZ4: =IF(ISNA(VLOOKUP(AZ$2,Holidays!$F$5:$G$33,2,FALSE)),"",VLOOKUP(AZ$2,Holidays!$F$5:$G$33,2,FALSE)) | BB4: =IF(ISNA(VLOOKUP(BB$2,Holidays!$F$5:$G$33,2,FALSE)),"",VLOOKUP(BB$2,Holidays!$F$5:$G$33,2,FALSE)) | BD4: =IF(ISNA(VLOOKUP(BD$2,Holidays!$F$5:$G$33,2,FALSE)),"",VLOOKUP(BD$2,Holidays!$F$5:$G$33,2,FALSE)) | BF4: =IF(ISNA(VLOOKUP(BF$2,Holidays!$F$5:$G$33,2,FALSE)),"",VLOOKUP(BF$2,Holidays!$F$5:$G$33,2,FALSE)) | BH4: =IF(ISNA(VLOOKUP(BH$2,Holidays!$F$5:$G$33,2,FALSE)),"",VLOOKUP(BH$2,Holidays!$F$5:$G$33,2,FALSE)) | BJ4: =IF(ISNA(VLOOKUP(BJ$2,Holidays!$F$5:$G$33,2,FALSE)),"",VLOOKUP(BJ$2,Holidays!$F$5:$G$33,2,FALSE)) | BL4: =IF(ISNA(VLOOKUP(BL$2,Holidays!$F$5:$G$33,2,FALSE)),"",VLOOKUP(BL$2,Holidays!$F$5:$G$33,2,FALSE)) | BN4: =IF(ISNA(VLOOKUP(BN$2,Holidays!$F$5:$G$33,2,FALSE)),"",VLOOKUP(BN$2,Holidays!$F$5:$G$33,2,FALSE)) | BP4: =IF(ISNA(VLOOKUP(BP$2,Holidays!$F$5:$G$33,2,FALSE)),"",VLOOKUP(BP$2,Holidays!$F$5:$G$33,2,FALSE)) | BR4: =IF(ISNA(VLOOKUP(BR$2,Holidays!$F$5:$G$33,2,FALSE)),"",VLOOKUP(BR$2,Holidays!$F$5:$G$33,2,FALSE))
J5: Item | K5: Amount | L5: Item | M5: Amount | N5: Item | O5: Amount | P5: Item | Q5: Amount | R5: Item | S5: Amount | T5: Item | U5: Amount | V5: Item | W5: Amount | X5: Item | Y5: Amount | Z5: Item | AA5: Amount | AB5: Item | AC5: Amount | AD5: Item | AE5: Amount | AF5: Item | AG5: Amount | AH5: Item | AI5: Amount | AJ5: Item | AK5: Amount | AL5: Item | AM5: Amount | AN5: Item | AO5: Amount | AP5: Item | AQ5: Amount | AR5: Item | AS5: Amount | AT5: Item | AU5: Amount | AV5: Item | AW5: Amount | AX5: Item | AY5: Amount | AZ5: Item | BA5: Amount | BB5: Item | BC5: Amount | BD5: Item | BE5: Amount | BF5: Item | BG5: Amount | BH5: Item | BI5: Amount | BJ5: Item | BK5: Amount | BL5: Item | BM5: Amount | BN5: Item | BO5: Amount
B6: Income This Month | F6: Living Expenses This Month | I6: Meals
B7: Item | C7: Amount | D7: Date Received | F7: Item | G7: Amount Spent
F8: Food (Meals) | G8: =SUM(J21:BS21)
F9: Household Goods Total | G9: =SUM(J22:BS27)
F10: Education & Enrichment | G10: =SUM(J28:BS28)
F11: All Other Items Total | G11: =SUM(J30:BS41)
B12: Total Income | C12: =SUM(C8:C11) | F12: Total Living Expenses | G12: =SUM(G8:G11)+SUM(J29:BS29)
B16: Fixed Expenses This Month
B17: Item | C17: Amount | D17: Date Paid | F17: Balance This Month | I17: Snacks
B18: Income offset | F18: =C12-C39-G12+SUM(J43:BS43)
B19: GAS
B20: Electricity & Water | I20: Dining Out
B21: RESP | F21: Cumulative Balance | I21: Total Food | K21: =SUM(K6:K20) | L21: =SUM(L6:L20) | M21: =SUM(M6:M20) | N21: =SUM(N6:N20) | O21: =SUM(O6:O20) | P21: =SUM(P6:P20) | Q21: =SUM(Q6:Q20) | R21: =SUM(R6:R20) | ... BS21: =SUM(BS6:BS20)
B22: Mobile Phone | F22: =F18+Jan!F22 | I22: Household Goods
B23: Daycare
B24: Rent / Mortgage
B25: Internet | F25: Notes This Month
B26: Car Insurance
B27: Property Tax
B28: Fuel / Maintenance | I28: Education & Enrichment
B29: Home Insurance | I29: Fuel
B30: Car Loan Payment | I30: Clothing
B31: Housing Management Fee
B32: Term Deposit | I32: Medical
B33: Pocket Money | I33: Hair & Cosmetics
B34: Savings | I34: Transportation
I35: Entertainment
I36: Gifts & Social
I37: Other
B39: Total Fixed Expenses | C39: =SUM(C18:C38)
I42: Daily Expenses Total | K42: =SUM(K21:K41) | M42: =SUM(M21:M41) | O42: =SUM(O21:O41) | Q42: =SUM(Q21:Q41) | S42: =SUM(S21:S41) | U42: =SUM(U21:U41) | W42: =SUM(W21:W41) | Y42: =SUM(Y21:Y41) | AA42: =SUM(AA21:AA41) | AC42: =SUM(AC21:AC41) | AE42: =SUM(AE21:AE41) | AG42: =SUM(AG21:AG41) | AI42: =SUM(AI21:AI41) | AK42: =SUM(AK21:AK41) | AM42: =SUM(AM21:AM41) | AO42: =SUM(AO21:AO41) | AQ42: =SUM(AQ21:AQ41) | AS42: =SUM(AS21:AS41) | AU42: =SUM(AU21:AU41) | AW42: =SUM(AW21:AW41) | AY42: =SUM(AY21:AY41) | BA42: =SUM(BA21:BA41) | BC42: =SUM(BC21:BC41) | BE42: =SUM(BE21:BE41) | BG42: =SUM(BG21:BG41) | BI42: =SUM(BI21:BI41) | BK42: =SUM(BK21:BK41) | BM42: =SUM(BM21:BM41) | BO42: =SUM(BO21:BO41) | BQ42: =SUM(BQ21:BQ41) | BS42: =SUM(BS21:BS41)
I43: Temporary Income
I44: Balance | K44: =$C$12-$C$39-K42+K43 | M44: =+K44-M42+M43 | O44: =+M44-O42+O43 | Q44: =+O44-Q42+Q43 | S44: =+Q44-S42+S43 | U44: =+S44-U42+U43 | W44: =+U44-W42+W43 | Y44: =+W44-Y42+Y43 | AA44: =+Y44-AA42+AA43 | AC44: =+AA44-AC42+AC43 | AE44: =+AC44-AE42+AE43 | AG44: =+AE44-AG42+AG43 | AI44: =+AG44-AI42+AI43 | AK44: =+AI44-AK42+AK43 | AM44: =+AK44-AM42+AM43 | AO44: =+AM44-AO42+AO43 | AQ44: =+AO44-AQ42+AQ43 | AS44: =+AQ44-AS42+AS43 | AU44: =+AS44-AU42+AU43 | AW44: =+AU44-AW42+AW43 | AY44: =+AW44-AY42+AY43 | BA44: =+AY44-BA42+BA43 | BC44: =+BA44-BC42+BC43 | BE44: =+BC44-BE42+BE43 | BG44: =+BE44-BG42+BG43 | BI44: =+BG44-BI42+BI43 | BK44: =+BI44-BK42+BK43 | BM44: =+BK44-BM42+BM43 | BO44: =+BM44-BO42+BO43 | BQ44: =+BO44-BQ42+BQ43 | BS44: =+BQ44-BS42+BS43
B47: Transactions this month One row per posted line. These rows are not included in the totals above. Payments are not listed.
B48: Card | C48: Trans date | D48: Post date | F48: Description | G48: Amount | I48: Category | J48: Receipt # | CA48: Txn key | CB48: Statement file | CC48: FX note | CD48: Status | CE48: Where written | CF48: Issuer category | CG48: Linked key
...

Sheet Mar
B1: =IF(OR(B2="",D2=""),"",DATE(B2,D2,1)) | C1: =IF(B1="","",DATE(YEAR(B1),MONTH(B1)+1,DAY(B1)-1))
B2: =IF('Annual Summary'!F5="","",'Annual Summary'!F5) | C2: / | D2: 3 | E2: Monthly Household Income & Expenses | I2: Daily Record | J2: =$B$1 | K2: =IF(J2="","",TEXT(J2,"ddd")) | L2: =IF(J2="","",IF(J2>=$C$1,"",J2+1)) | M2: =IF(L2="","",TEXT(L2,"ddd")) | N2: =IF(L2="","",IF(L2>=$C$1,"",L2+1)) | O2: =IF(N2="","",TEXT(N2,"ddd")) | P2: =IF(N2="","",IF(N2>=$C$1,"",N2+1)) | Q2: =IF(P2="","",TEXT(P2,"ddd")) | R2: =IF(P2="","",IF(P2>=$C$1,"",P2+1)) | S2: =IF(R2="","",TEXT(R2,"ddd")) | T2: =IF(R2="","",IF(R2>=$C$1,"",R2+1)) | U2: =IF(T2="","",TEXT(T2,"ddd")) | V2: =IF(T2="","",IF(T2>=$C$1,"",T2+1)) | W2: =IF(V2="","",TEXT(V2,"ddd")) | X2: =IF(V2="","",IF(V2>=$C$1,"",V2+1)) | Y2: =IF(X2="","",TEXT(X2,"ddd")) | Z2: =IF(X2="","",IF(X2>=$C$1,"",X2+1)) | AA2: =IF(Z2="","",TEXT(Z2,"ddd")) | AB2: =IF(Z2="","",IF(Z2>=$C$1,"",Z2+1)) | AC2: =IF(AB2="","",TEXT(AB2,"ddd")) | AD2: =IF(AB2="","",IF(AB2>=$C$1,"",AB2+1)) | AE2: =IF(AD2="","",TEXT(AD2,"ddd")) | AF2: =IF(AD2="","",IF(AD2>=$C$1,"",AD2+1)) | AG2: =IF(AF2="","",TEXT(AF2,"ddd")) | AH2: =IF(AF2="","",IF(AF2>=$C$1,"",AF2+1)) | AI2: =IF(AH2="","",TEXT(AH2,"ddd")) | AJ2: =IF(AH2="","",IF(AH2>=$C$1,"",AH2+1)) | AK2: =IF(AJ2="","",TEXT(AJ2,"ddd")) | AL2: =IF(AJ2="","",IF(AJ2>=$C$1,"",AJ2+1)) | AM2: =IF(AL2="","",TEXT(AL2,"ddd")) | AN2: =IF(AL2="","",IF(AL2>=$C$1,"",AL2+1)) | AO2: =IF(AN2="","",TEXT(AN2,"ddd")) | AP2: =IF(AN2="","",IF(AN2>=$C$1,"",AN2+1)) | AQ2: =IF(AP2="","",TEXT(AP2,"ddd")) | AR2: =IF(AP2="","",IF(AP2>=$C$1,"",AP2+1)) | AS2: =IF(AR2="","",TEXT(AR2,"ddd")) | AT2: =IF(AR2="","",IF(AR2>=$C$1,"",AR2+1)) | AU2: =IF(AT2="","",TEXT(AT2,"ddd")) | AV2: =IF(AT2="","",IF(AT2>=$C$1,"",AT2+1)) | AW2: =IF(AV2="","",TEXT(AV2,"ddd")) | AX2: =IF(AV2="","",IF(AV2>=$C$1,"",AV2+1)) | AY2: =IF(AX2="","",TEXT(AX2,"ddd")) | AZ2: =IF(AX2="","",IF(AX2>=$C$1,"",AX2+1)) | BA2: =IF(AZ2="","",TEXT(AZ2,"ddd")) | BB2: =IF(AZ2="","",IF(AZ2>=$C$1,"",AZ2+1)) | BC2: =IF(BB2="","",TEXT(BB2,"ddd")) | BD2: =IF(BB2="","",IF(BB2>=$C$1,"",BB2+1)) | BE2: =IF(BD2="","",TEXT(BD2,"ddd")) | BF2: =IF(BD2="","",IF(BD2>=$C$1,"",BD2+1)) | BG2: =IF(BF2="","",TEXT(BF2,"ddd")) | BH2: =IF(BF2="","",IF(BF2>=$C$1,"",BF2+1)) | BI2: =IF(BH2="","",TEXT(BH2,"ddd")) | BJ2: =IF(BH2="","",IF(BH2>=$C$1,"",BH2+1)) | BK2: =IF(BJ2="","",TEXT(BJ2,"ddd")) | BL2: =IF(BJ2="","",IF(BJ2>=$C$1,"",BJ2+1)) | BM2: =IF(BL2="","",TEXT(BL2,"ddd")) | BN2: =IF(BL2="","",IF(BL2>=$C$1,"",BL2+1)) | BO2: =IF(BN2="","",TEXT(BN2,"ddd")) | BP2: =IF(BN2="","",IF(BN2>=$C$1,"",BN2+1)) | BQ2: =IF(BP2="","",TEXT(BP2,"ddd")) | BR2: =IF(BP2="","",IF(BP2>=$C$1,"",BP2+1)) | BS2: =IF(BR2="","",TEXT(BR2,"ddd"))
I3: Holiday | J3: =IF(ISNA(VLOOKUP(J$2,Holidays!$B$5:$C$33,2,FALSE)),"",VLOOKUP(J$2,Holidays!$B$5:$C$33,2,FALSE)) | L3: =IF(ISNA(VLOOKUP(L$2,Holidays!$B$5:$C$33,2,FALSE)),"",VLOOKUP(L$2,Holidays!$B$5:$C$33,2,FALSE)) | N3: =IF(ISNA(VLOOKUP(N$2,Holidays!$B$5:$C$33,2,FALSE)),"",VLOOKUP(N$2,Holidays!$B$5:$C$33,2,FALSE)) | P3: =IF(ISNA(VLOOKUP(P$2,Holidays!$B$5:$C$33,2,FALSE)),"",VLOOKUP(P$2,Holidays!$B$5:$C$33,2,FALSE)) | R3: =IF(ISNA(VLOOKUP(R$2,Holidays!$B$5:$C$33,2,FALSE)),"",VLOOKUP(R$2,Holidays!$B$5:$C$33,2,FALSE)) | T3: =IF(ISNA(VLOOKUP(T$2,Holidays!$B$5:$C$33,2,FALSE)),"",VLOOKUP(T$2,Holidays!$B$5:$C$33,2,FALSE)) | V3: =IF(ISNA(VLOOKUP(V$2,Holidays!$B$5:$C$33,2,FALSE)),"",VLOOKUP(V$2,Holidays!$B$5:$C$33,2,FALSE)) | X3: =IF(ISNA(VLOOKUP(X$2,Holidays!$B$5:$C$33,2,FALSE)),"",VLOOKUP(X$2,Holidays!$B$5:$C$33,2,FALSE)) | Z3: =IF(ISNA(VLOOKUP(Z$2,Holidays!$B$5:$C$33,2,FALSE)),"",VLOOKUP(Z$2,Holidays!$B$5:$C$33,2,FALSE)) | AB3: =IF(ISNA(VLOOKUP(AB$2,Holidays!$B$5:$C$33,2,FALSE)),"",VLOOKUP(AB$2,Holidays!$B$5:$C$33,2,FALSE)) | AD3: =IF(ISNA(VLOOKUP(AD$2,Holidays!$B$5:$C$33,2,FALSE)),"",VLOOKUP(AD$2,Holidays!$B$5:$C$33,2,FALSE)) | AF3: =IF(ISNA(VLOOKUP(AF$2,Holidays!$B$5:$C$33,2,FALSE)),"",VLOOKUP(AF$2,Holidays!$B$5:$C$33,2,FALSE)) | AH3: =IF(ISNA(VLOOKUP(AH$2,Holidays!$B$5:$C$33,2,FALSE)),"",VLOOKUP(AH$2,Holidays!$B$5:$C$33,2,FALSE)) | AJ3: =IF(ISNA(VLOOKUP(AJ$2,Holidays!$B$5:$C$33,2,FALSE)),"",VLOOKUP(AJ$2,Holidays!$B$5:$C$33,2,FALSE)) | AL3: =IF(ISNA(VLOOKUP(AL$2,Holidays!$B$5:$C$33,2,FALSE)),"",VLOOKUP(AL$2,Holidays!$B$5:$C$33,2,FALSE)) | AN3: =IF(ISNA(VLOOKUP(AN$2,Holidays!$B$5:$C$33,2,FALSE)),"",VLOOKUP(AN$2,Holidays!$B$5:$C$33,2,FALSE)) | AP3: =IF(ISNA(VLOOKUP(AP$2,Holidays!$B$5:$C$33,2,FALSE)),"",VLOOKUP(AP$2,Holidays!$B$5:$C$33,2,FALSE)) | AR3: =IF(ISNA(VLOOKUP(AR$2,Holidays!$B$5:$C$33,2,FALSE)),"",VLOOKUP(AR$2,Holidays!$B$5:$C$33,2,FALSE)) | AT3: =IF(ISNA(VLOOKUP(AT$2,Holidays!$B$5:$C$33,2,FALSE)),"",VLOOKUP(AT$2,Holidays!$B$5:$C$33,2,FALSE)) | AV3: =IF(ISNA(VLOOKUP(AV$2,Holidays!$B$5:$C$33,2,FALSE)),"",VLOOKUP(AV$2,Holidays!$B$5:$C$33,2,FALSE)) | AX3: =IF(ISNA(VLOOKUP(AX$2,Holidays!$B$5:$C$33,2,FALSE)),"",VLOOKUP(AX$2,Holidays!$B$5:$C$33,2,FALSE)) | AZ3: =IF(ISNA(VLOOKUP(AZ$2,Holidays!$B$5:$C$33,2,FALSE)),"",VLOOKUP(AZ$2,Holidays!$B$5:$C$33,2,FALSE)) | BB3: =IF(ISNA(VLOOKUP(BB$2,Holidays!$B$5:$C$33,2,FALSE)),"",VLOOKUP(BB$2,Holidays!$B$5:$C$33,2,FALSE)) | BD3: =IF(ISNA(VLOOKUP(BD$2,Holidays!$B$5:$C$33,2,FALSE)),"",VLOOKUP(BD$2,Holidays!$B$5:$C$33,2,FALSE)) | BF3: =IF(ISNA(VLOOKUP(BF$2,Holidays!$B$5:$C$33,2,FALSE)),"",VLOOKUP(BF$2,Holidays!$B$5:$C$33,2,FALSE)) | BH3: =IF(ISNA(VLOOKUP(BH$2,Holidays!$B$5:$C$33,2,FALSE)),"",VLOOKUP(BH$2,Holidays!$B$5:$C$33,2,FALSE)) | BJ3: =IF(ISNA(VLOOKUP(BJ$2,Holidays!$B$5:$C$33,2,FALSE)),"",VLOOKUP(BJ$2,Holidays!$B$5:$C$33,2,FALSE)) | BL3: =IF(ISNA(VLOOKUP(BL$2,Holidays!$B$5:$C$33,2,FALSE)),"",VLOOKUP(BL$2,Holidays!$B$5:$C$33,2,FALSE)) | BN3: =IF(ISNA(VLOOKUP(BN$2,Holidays!$B$5:$C$33,2,FALSE)),"",VLOOKUP(BN$2,Holidays!$B$5:$C$33,2,FALSE)) | BP3: =IF(ISNA(VLOOKUP(BP$2,Holidays!$B$5:$C$33,2,FALSE)),"",VLOOKUP(BP$2,Holidays!$B$5:$C$33,2,FALSE)) | BR3: =IF(ISNA(VLOOKUP(BR$2,Holidays!$B$5:$C$33,2,FALSE)),"",VLOOKUP(BR$2,Holidays!$B$5:$C$33,2,FALSE))
F4: Back to Annual Summary | I4: Anniversary | J4: =IF(ISNA(VLOOKUP(J$2,Holidays!$F$5:$G$33,2,FALSE)),"",VLOOKUP(J$2,Holidays!$F$5:$G$33,2,FALSE)) | L4: =IF(ISNA(VLOOKUP(L$2,Holidays!$F$5:$G$33,2,FALSE)),"",VLOOKUP(L$2,Holidays!$F$5:$G$33,2,FALSE)) | N4: =IF(ISNA(VLOOKUP(N$2,Holidays!$F$5:$G$33,2,FALSE)),"",VLOOKUP(N$2,Holidays!$F$5:$G$33,2,FALSE)) | P4: =IF(ISNA(VLOOKUP(P$2,Holidays!$F$5:$G$33,2,FALSE)),"",VLOOKUP(P$2,Holidays!$F$5:$G$33,2,FALSE)) | R4: =IF(ISNA(VLOOKUP(R$2,Holidays!$F$5:$G$33,2,FALSE)),"",VLOOKUP(R$2,Holidays!$F$5:$G$33,2,FALSE)) | T4: =IF(ISNA(VLOOKUP(T$2,Holidays!$F$5:$G$33,2,FALSE)),"",VLOOKUP(T$2,Holidays!$F$5:$G$33,2,FALSE)) | V4: =IF(ISNA(VLOOKUP(V$2,Holidays!$F$5:$G$33,2,FALSE)),"",VLOOKUP(V$2,Holidays!$F$5:$G$33,2,FALSE)) | X4: =IF(ISNA(VLOOKUP(X$2,Holidays!$F$5:$G$33,2,FALSE)),"",VLOOKUP(X$2,Holidays!$F$5:$G$33,2,FALSE)) | Z4: =IF(ISNA(VLOOKUP(Z$2,Holidays!$F$5:$G$33,2,FALSE)),"",VLOOKUP(Z$2,Holidays!$F$5:$G$33,2,FALSE)) | AB4: =IF(ISNA(VLOOKUP(AB$2,Holidays!$F$5:$G$33,2,FALSE)),"",VLOOKUP(AB$2,Holidays!$F$5:$G$33,2,FALSE)) | AD4: =IF(ISNA(VLOOKUP(AD$2,Holidays!$F$5:$G$33,2,FALSE)),"",VLOOKUP(AD$2,Holidays!$F$5:$G$33,2,FALSE)) | AF4: =IF(ISNA(VLOOKUP(AF$2,Holidays!$F$5:$G$33,2,FALSE)),"",VLOOKUP(AF$2,Holidays!$F$5:$G$33,2,FALSE)) | AH4: =IF(ISNA(VLOOKUP(AH$2,Holidays!$F$5:$G$33,2,FALSE)),"",VLOOKUP(AH$2,Holidays!$F$5:$G$33,2,FALSE)) | AJ4: =IF(ISNA(VLOOKUP(AJ$2,Holidays!$F$5:$G$33,2,FALSE)),"",VLOOKUP(AJ$2,Holidays!$F$5:$G$33,2,FALSE)) | AL4: =IF(ISNA(VLOOKUP(AL$2,Holidays!$F$5:$G$33,2,FALSE)),"",VLOOKUP(AL$2,Holidays!$F$5:$G$33,2,FALSE)) | AN4: =IF(ISNA(VLOOKUP(AN$2,Holidays!$F$5:$G$33,2,FALSE)),"",VLOOKUP(AN$2,Holidays!$F$5:$G$33,2,FALSE)) | AP4: =IF(ISNA(VLOOKUP(AP$2,Holidays!$F$5:$G$33,2,FALSE)),"",VLOOKUP(AP$2,Holidays!$F$5:$G$33,2,FALSE)) | AR4: =IF(ISNA(VLOOKUP(AR$2,Holidays!$F$5:$G$33,2,FALSE)),"",VLOOKUP(AR$2,Holidays!$F$5:$G$33,2,FALSE)) | AT4: =IF(ISNA(VLOOKUP(AT$2,Holidays!$F$5:$G$33,2,FALSE)),"",VLOOKUP(AT$2,Holidays!$F$5:$G$33,2,FALSE)) | AV4: =IF(ISNA(VLOOKUP(AV$2,Holidays!$F$5:$G$33,2,FALSE)),"",VLOOKUP(AV$2,Holidays!$F$5:$G$33,2,FALSE)) | AX4: =IF(ISNA(VLOOKUP(AX$2,Holidays!$F$5:$G$33,2,FALSE)),"",VLOOKUP(AX$2,Holidays!$F$5:$G$33,2,FALSE)) | AZ4: =IF(ISNA(VLOOKUP(AZ$2,Holidays!$F$5:$G$33,2,FALSE)),"",VLOOKUP(AZ$2,Holidays!$F$5:$G$33,2,FALSE)) | BB4: =IF(ISNA(VLOOKUP(BB$2,Holidays!$F$5:$G$33,2,FALSE)),"",VLOOKUP(BB$2,Holidays!$F$5:$G$33,2,FALSE)) | BD4: =IF(ISNA(VLOOKUP(BD$2,Holidays!$F$5:$G$33,2,FALSE)),"",VLOOKUP(BD$2,Holidays!$F$5:$G$33,2,FALSE)) | BF4: =IF(ISNA(VLOOKUP(BF$2,Holidays!$F$5:$G$33,2,FALSE)),"",VLOOKUP(BF$2,Holidays!$F$5:$G$33,2,FALSE)) | BH4: =IF(ISNA(VLOOKUP(BH$2,Holidays!$F$5:$G$33,2,FALSE)),"",VLOOKUP(BH$2,Holidays!$F$5:$G$33,2,FALSE)) | BJ4: =IF(ISNA(VLOOKUP(BJ$2,Holidays!$F$5:$G$33,2,FALSE)),"",VLOOKUP(BJ$2,Holidays!$F$5:$G$33,2,FALSE)) | BL4: =IF(ISNA(VLOOKUP(BL$2,Holidays!$F$5:$G$33,2,FALSE)),"",VLOOKUP(BL$2,Holidays!$F$5:$G$33,2,FALSE)) | BN4: =IF(ISNA(VLOOKUP(BN$2,Holidays!$F$5:$G$33,2,FALSE)),"",VLOOKUP(BN$2,Holidays!$F$5:$G$33,2,FALSE)) | BP4: =IF(ISNA(VLOOKUP(BP$2,Holidays!$F$5:$G$33,2,FALSE)),"",VLOOKUP(BP$2,Holidays!$F$5:$G$33,2,FALSE)) | BR4: =IF(ISNA(VLOOKUP(BR$2,Holidays!$F$5:$G$33,2,FALSE)),"",VLOOKUP(BR$2,Holidays!$F$5:$G$33,2,FALSE))
J5: Item | K5: Amount | L5: Item | M5: Amount | N5: Item | O5: Amount | P5: Item | Q5: Amount | R5: Item | S5: Amount | T5: Item | U5: Amount | V5: Item | W5: Amount | X5: Item | Y5: Amount | Z5: Item | AA5: Amount | AB5: Item | AC5: Amount | AD5: Item | AE5: Amount | AF5: Item | AG5: Amount | AH5: Item | AI5: Amount | AJ5: Item | AK5: Amount | AL5: Item | AM5: Amount | AN5: Item | AO5: Amount | AP5: Item | AQ5: Amount | AR5: Item | AS5: Amount | AT5: Item | AU5: Amount | AV5: Item | AW5: Amount | AX5: Item | AY5: Amount | AZ5: Item | BA5: Amount | BB5: Item | BC5: Amount | BD5: Item | BE5: Amount | BF5: Item | BG5: Amount | BH5: Item | BI5: Amount | BJ5: Item | BK5: Amount | BL5: Item | BM5: Amount | BN5: Item | BO5: Amount | BP5: Item | BQ5: Amount | BR5: Item | BS5: Amount
B6: Income This Month | F6: Living Expenses This Month | I6: Meals
B7: Item | C7: Amount | D7: Date Received | F7: Item | G7: Amount Spent
F8: Food (Meals) | G8: =SUM(J21:BS21)
F9: Household Goods Total | G9: =SUM(J22:BS27)
F10: Education & Enrichment | G10: =SUM(J28:BS28)
F11: All Other Items Total | G11: =SUM(J30:BS41)
B12: Total Income | C12: =SUM(C8:C11) | F12: Total Living Expenses | G12: =SUM(G8:G11)+SUM(J29:BS29)
B16: Fixed Expenses This Month
B17: Item | C17: Amount | D17: Date Paid | F17: Balance This Month | I17: Snacks & Groceries
B18: Income offset | F18: =C12-C39-G12+SUM(J43:BS43)
B19: GAS
B20: Electricity & Water | I20: Dining Out
B21: RESP | F21: Cumulative Balance | I21: Total Food | K21: =SUM(K6:K20) | L21: =SUM(L6:L20) | M21: =SUM(M6:M20) | N21: =SUM(N6:N20) | O21: =SUM(O6:O20) | P21: =SUM(P6:P20) | Q21: =SUM(Q6:Q20) | R21: =SUM(R6:R20) | ... BS21: =SUM(BS6:BS20)
B22: Mobile Phone | F22: =F18+Feb!F22 | I22: Household Goods
B23: Daycare
B24: Rent / Mortgage
B25: Internet | F25: Notes This Month
B26: Car Insurance
B27: Property Tax
B28: Fuel / Maintenance | I28: Education & Enrichment
B29: Home Insurance | I29: Fuel
B30: Car Loan Payment | I30: Clothing
B31: Housing Management Fee
B32: Term Deposit | I32: Medical
B33: Pocket Money | I33: Hair & Cosmetics
B34: Savings | I34: Transportation
I35: Entertainment
I36: Gifts & Social
I37: Other
B39: Total Fixed Expenses | C39: =SUM(C18:C38)
I42: Daily Expenses Total | K42: =SUM(K21:K41) | M42: =SUM(M21:M41) | O42: =SUM(O21:O41) | Q42: =SUM(Q21:Q41) | S42: =SUM(S21:S41) | U42: =SUM(U21:U41) | W42: =SUM(W21:W41) | Y42: =SUM(Y21:Y41) | AA42: =SUM(AA21:AA41) | AC42: =SUM(AC21:AC41) | AE42: =SUM(AE21:AE41) | AG42: =SUM(AG21:AG41) | AI42: =SUM(AI21:AI41) | AK42: =SUM(AK21:AK41) | AM42: =SUM(AM21:AM41) | AO42: =SUM(AO21:AO41) | AQ42: =SUM(AQ21:AQ41) | AS42: =SUM(AS21:AS41) | AU42: =SUM(AU21:AU41) | AW42: =SUM(AW21:AW41) | AY42: =SUM(AY21:AY41) | BA42: =SUM(BA21:BA41) | BC42: =SUM(BC21:BC41) | BE42: =SUM(BE21:BE41) | BG42: =SUM(BG21:BG41) | BI42: =SUM(BI21:BI41) | BK42: =SUM(BK21:BK41) | BM42: =SUM(BM21:BM41) | BO42: =SUM(BO21:BO41) | BQ42: =SUM(BQ21:BQ41) | BS42: =SUM(BS21:BS41)
I43: Temporary Income
I44: Balance | K44: =$C$12-$C$39-K42+K43 | M44: =+K44-M42+M43 | O44: =+M44-O42+O43 | Q44: =+O44-Q42+Q43 | S44: =+Q44-S42+S43 | U44: =+S44-U42+U43 | W44: =+U44-W42+W43 | Y44: =+W44-Y42+Y43 | AA44: =+Y44-AA42+AA43 | AC44: =+AA44-AC42+AC43 | AE44: =+AC44-AE42+AE43 | AG44: =+AE44-AG42+AG43 | AI44: =+AG44-AI42+AI43 | AK44: =+AI44-AK42+AK43 | AM44: =+AK44-AM42+AM43 | AO44: =+AM44-AO42+AO43 | AQ44: =+AO44-AQ42+AQ43 | AS44: =+AQ44-AS42+AS43 | AU44: =+AS44-AU42+AU43 | AW44: =+AU44-AW42+AW43 | AY44: =+AW44-AY42+AY43 | BA44: =+AY44-BA42+BA43 | BC44: =+BA44-BC42+BC43 | BE44: =+BC44-BE42+BE43 | BG44: =+BE44-BG42+BG43 | BI44: =+BG44-BI42+BI43 | BK44: =+BI44-BK42+BK43 | BM44: =+BK44-BM42+BM43 | BO44: =+BM44-BO42+BO43 | BQ44: =+BO44-BQ42+BQ43 | BS44: =+BQ44-BS42+BS43
B47: Transactions this month One row per posted line. These rows are not included in the totals above. Payments are not listed.
B48: Card | C48: Trans date | D48: Post date | F48: Description | G48: Amount | I48: Category | J48: Receipt # | CA48: Txn key | CB48: Statement file | CC48: FX note | CD48: Status | CE48: Where written | CF48: Issuer category | CG48: Linked key
...

Sheet Apr
B1: =IF(OR(B2="",D2=""),"",DATE(B2,D2,1)) | C1: =IF(B1="","",DATE(YEAR(B1),MONTH(B1)+1,DAY(B1)-1))
B2: =IF('Annual Summary'!F5="","",'Annual Summary'!F5) | C2: / | D2: 4 | E2: Monthly Household Income & Expenses | I2: Daily Record | J2: =$B$1 | K2: =IF(J2="","",TEXT(J2,"ddd")) | L2: =IF(J2="","",IF(J2>=$C$1,"",J2+1)) | M2: =IF(L2="","",TEXT(L2,"ddd")) | N2: =IF(L2="","",IF(L2>=$C$1,"",L2+1)) | O2: =IF(N2="","",TEXT(N2,"ddd")) | P2: =IF(N2="","",IF(N2>=$C$1,"",N2+1)) | Q2: =IF(P2="","",TEXT(P2,"ddd")) | R2: =IF(P2="","",IF(P2>=$C$1,"",P2+1)) | S2: =IF(R2="","",TEXT(R2,"ddd")) | T2: =IF(R2="","",IF(R2>=$C$1,"",R2+1)) | U2: =IF(T2="","",TEXT(T2,"ddd")) | V2: =IF(T2="","",IF(T2>=$C$1,"",T2+1)) | W2: =IF(V2="","",TEXT(V2,"ddd")) | X2: =IF(V2="","",IF(V2>=$C$1,"",V2+1)) | Y2: =IF(X2="","",TEXT(X2,"ddd")) | Z2: =IF(X2="","",IF(X2>=$C$1,"",X2+1)) | AA2: =IF(Z2="","",TEXT(Z2,"ddd")) | AB2: =IF(Z2="","",IF(Z2>=$C$1,"",Z2+1)) | AC2: =IF(AB2="","",TEXT(AB2,"ddd")) | AD2: =IF(AB2="","",IF(AB2>=$C$1,"",AB2+1)) | AE2: =IF(AD2="","",TEXT(AD2,"ddd")) | AF2: =IF(AD2="","",IF(AD2>=$C$1,"",AD2+1)) | AG2: =IF(AF2="","",TEXT(AF2,"ddd")) | AH2: =IF(AF2="","",IF(AF2>=$C$1,"",AF2+1)) | AI2: =IF(AH2="","",TEXT(AH2,"ddd")) | AJ2: =IF(AH2="","",IF(AH2>=$C$1,"",AH2+1)) | AK2: =IF(AJ2="","",TEXT(AJ2,"ddd")) | AL2: =IF(AJ2="","",IF(AJ2>=$C$1,"",AJ2+1)) | AM2: =IF(AL2="","",TEXT(AL2,"ddd")) | AN2: =IF(AL2="","",IF(AL2>=$C$1,"",AL2+1)) | AO2: =IF(AN2="","",TEXT(AN2,"ddd")) | AP2: =IF(AN2="","",IF(AN2>=$C$1,"",AN2+1)) | AQ2: =IF(AP2="","",TEXT(AP2,"ddd")) | AR2: =IF(AP2="","",IF(AP2>=$C$1,"",AP2+1)) | AS2: =IF(AR2="","",TEXT(AR2,"ddd")) | AT2: =IF(AR2="","",IF(AR2>=$C$1,"",AR2+1)) | AU2: =IF(AT2="","",TEXT(AT2,"ddd")) | AV2: =IF(AT2="","",IF(AT2>=$C$1,"",AT2+1)) | AW2: =IF(AV2="","",TEXT(AV2,"ddd")) | AX2: =IF(AV2="","",IF(AV2>=$C$1,"",AV2+1)) | AY2: =IF(AX2="","",TEXT(AX2,"ddd")) | AZ2: =IF(AX2="","",IF(AX2>=$C$1,"",AX2+1)) | BA2: =IF(AZ2="","",TEXT(AZ2,"ddd")) | BB2: =IF(AZ2="","",IF(AZ2>=$C$1,"",AZ2+1)) | BC2: =IF(BB2="","",TEXT(BB2,"ddd")) | BD2: =IF(BB2="","",IF(BB2>=$C$1,"",BB2+1)) | BE2: =IF(BD2="","",TEXT(BD2,"ddd")) | BF2: =IF(BD2="","",IF(BD2>=$C$1,"",BD2+1)) | BG2: =IF(BF2="","",TEXT(BF2,"ddd")) | BH2: =IF(BF2="","",IF(BF2>=$C$1,"",BF2+1)) | BI2: =IF(BH2="","",TEXT(BH2,"ddd")) | BJ2: =IF(BH2="","",IF(BH2>=$C$1,"",BH2+1)) | BK2: =IF(BJ2="","",TEXT(BJ2,"ddd")) | BL2: =IF(BJ2="","",IF(BJ2>=$C$1,"",BJ2+1)) | BM2: =IF(BL2="","",TEXT(BL2,"ddd")) | BN2: =IF(BL2="","",IF(BL2>=$C$1,"",BL2+1)) | BO2: =IF(BN2="","",TEXT(BN2,"ddd")) | BP2: =IF(BN2="","",IF(BN2>=$C$1,"",BN2+1)) | BQ2: =IF(BP2="","",TEXT(BP2,"ddd"))
I3: Holiday | J3: =IF(ISNA(VLOOKUP(J$2,Holidays!$B$5:$C$33,2,FALSE)),"",VLOOKUP(J$2,Holidays!$B$5:$C$33,2,FALSE)) | L3: =IF(ISNA(VLOOKUP(L$2,Holidays!$B$5:$C$33,2,FALSE)),"",VLOOKUP(L$2,Holidays!$B$5:$C$33,2,FALSE)) | N3: =IF(ISNA(VLOOKUP(N$2,Holidays!$B$5:$C$33,2,FALSE)),"",VLOOKUP(N$2,Holidays!$B$5:$C$33,2,FALSE)) | P3: =IF(ISNA(VLOOKUP(P$2,Holidays!$B$5:$C$33,2,FALSE)),"",VLOOKUP(P$2,Holidays!$B$5:$C$33,2,FALSE)) | R3: =IF(ISNA(VLOOKUP(R$2,Holidays!$B$5:$C$33,2,FALSE)),"",VLOOKUP(R$2,Holidays!$B$5:$C$33,2,FALSE)) | T3: =IF(ISNA(VLOOKUP(T$2,Holidays!$B$5:$C$33,2,FALSE)),"",VLOOKUP(T$2,Holidays!$B$5:$C$33,2,FALSE)) | V3: =IF(ISNA(VLOOKUP(V$2,Holidays!$B$5:$C$33,2,FALSE)),"",VLOOKUP(V$2,Holidays!$B$5:$C$33,2,FALSE)) | X3: =IF(ISNA(VLOOKUP(X$2,Holidays!$B$5:$C$33,2,FALSE)),"",VLOOKUP(X$2,Holidays!$B$5:$C$33,2,FALSE)) | Z3: =IF(ISNA(VLOOKUP(Z$2,Holidays!$B$5:$C$33,2,FALSE)),"",VLOOKUP(Z$2,Holidays!$B$5:$C$33,2,FALSE)) | AB3: =IF(ISNA(VLOOKUP(AB$2,Holidays!$B$5:$C$33,2,FALSE)),"",VLOOKUP(AB$2,Holidays!$B$5:$C$33,2,FALSE)) | AD3: =IF(ISNA(VLOOKUP(AD$2,Holidays!$B$5:$C$33,2,FALSE)),"",VLOOKUP(AD$2,Holidays!$B$5:$C$33,2,FALSE)) | AF3: =IF(ISNA(VLOOKUP(AF$2,Holidays!$B$5:$C$33,2,FALSE)),"",VLOOKUP(AF$2,Holidays!$B$5:$C$33,2,FALSE)) | AH3: =IF(ISNA(VLOOKUP(AH$2,Holidays!$B$5:$C$33,2,FALSE)),"",VLOOKUP(AH$2,Holidays!$B$5:$C$33,2,FALSE)) | AJ3: =IF(ISNA(VLOOKUP(AJ$2,Holidays!$B$5:$C$33,2,FALSE)),"",VLOOKUP(AJ$2,Holidays!$B$5:$C$33,2,FALSE)) | AL3: =IF(ISNA(VLOOKUP(AL$2,Holidays!$B$5:$C$33,2,FALSE)),"",VLOOKUP(AL$2,Holidays!$B$5:$C$33,2,FALSE)) | AN3: =IF(ISNA(VLOOKUP(AN$2,Holidays!$B$5:$C$33,2,FALSE)),"",VLOOKUP(AN$2,Holidays!$B$5:$C$33,2,FALSE)) | AP3: =IF(ISNA(VLOOKUP(AP$2,Holidays!$B$5:$C$33,2,FALSE)),"",VLOOKUP(AP$2,Holidays!$B$5:$C$33,2,FALSE)) | AR3: =IF(ISNA(VLOOKUP(AR$2,Holidays!$B$5:$C$33,2,FALSE)),"",VLOOKUP(AR$2,Holidays!$B$5:$C$33,2,FALSE)) | AT3: =IF(ISNA(VLOOKUP(AT$2,Holidays!$B$5:$C$33,2,FALSE)),"",VLOOKUP(AT$2,Holidays!$B$5:$C$33,2,FALSE)) | AV3: =IF(ISNA(VLOOKUP(AV$2,Holidays!$B$5:$C$33,2,FALSE)),"",VLOOKUP(AV$2,Holidays!$B$5:$C$33,2,FALSE)) | AX3: =IF(ISNA(VLOOKUP(AX$2,Holidays!$B$5:$C$33,2,FALSE)),"",VLOOKUP(AX$2,Holidays!$B$5:$C$33,2,FALSE)) | AZ3: =IF(ISNA(VLOOKUP(AZ$2,Holidays!$B$5:$C$33,2,FALSE)),"",VLOOKUP(AZ$2,Holidays!$B$5:$C$33,2,FALSE)) | BB3: =IF(ISNA(VLOOKUP(BB$2,Holidays!$B$5:$C$33,2,FALSE)),"",VLOOKUP(BB$2,Holidays!$B$5:$C$33,2,FALSE)) | BD3: =IF(ISNA(VLOOKUP(BD$2,Holidays!$B$5:$C$33,2,FALSE)),"",VLOOKUP(BD$2,Holidays!$B$5:$C$33,2,FALSE)) | BF3: =IF(ISNA(VLOOKUP(BF$2,Holidays!$B$5:$C$33,2,FALSE)),"",VLOOKUP(BF$2,Holidays!$B$5:$C$33,2,FALSE)) | BH3: =IF(ISNA(VLOOKUP(BH$2,Holidays!$B$5:$C$33,2,FALSE)),"",VLOOKUP(BH$2,Holidays!$B$5:$C$33,2,FALSE)) | BJ3: =IF(ISNA(VLOOKUP(BJ$2,Holidays!$B$5:$C$33,2,FALSE)),"",VLOOKUP(BJ$2,Holidays!$B$5:$C$33,2,FALSE)) | BL3: =IF(ISNA(VLOOKUP(BL$2,Holidays!$B$5:$C$33,2,FALSE)),"",VLOOKUP(BL$2,Holidays!$B$5:$C$33,2,FALSE)) | BN3: =IF(ISNA(VLOOKUP(BN$2,Holidays!$B$5:$C$33,2,FALSE)),"",VLOOKUP(BN$2,Holidays!$B$5:$C$33,2,FALSE)) | BP3: =IF(ISNA(VLOOKUP(BP$2,Holidays!$B$5:$C$33,2,FALSE)),"",VLOOKUP(BP$2,Holidays!$B$5:$C$33,2,FALSE)) | BR3: =IF(ISNA(VLOOKUP(BR$2,Holidays!$B$5:$C$33,2,FALSE)),"",VLOOKUP(BR$2,Holidays!$B$5:$C$33,2,FALSE))
F4: Back to Annual Summary | I4: Anniversary | J4: =IF(ISNA(VLOOKUP(J$2,Holidays!$F$5:$G$33,2,FALSE)),"",VLOOKUP(J$2,Holidays!$F$5:$G$33,2,FALSE)) | L4: =IF(ISNA(VLOOKUP(L$2,Holidays!$F$5:$G$33,2,FALSE)),"",VLOOKUP(L$2,Holidays!$F$5:$G$33,2,FALSE)) | N4: =IF(ISNA(VLOOKUP(N$2,Holidays!$F$5:$G$33,2,FALSE)),"",VLOOKUP(N$2,Holidays!$F$5:$G$33,2,FALSE)) | P4: =IF(ISNA(VLOOKUP(P$2,Holidays!$F$5:$G$33,2,FALSE)),"",VLOOKUP(P$2,Holidays!$F$5:$G$33,2,FALSE)) | R4: =IF(ISNA(VLOOKUP(R$2,Holidays!$F$5:$G$33,2,FALSE)),"",VLOOKUP(R$2,Holidays!$F$5:$G$33,2,FALSE)) | T4: =IF(ISNA(VLOOKUP(T$2,Holidays!$F$5:$G$33,2,FALSE)),"",VLOOKUP(T$2,Holidays!$F$5:$G$33,2,FALSE)) | V4: =IF(ISNA(VLOOKUP(V$2,Holidays!$F$5:$G$33,2,FALSE)),"",VLOOKUP(V$2,Holidays!$F$5:$G$33,2,FALSE)) | X4: =IF(ISNA(VLOOKUP(X$2,Holidays!$F$5:$G$33,2,FALSE)),"",VLOOKUP(X$2,Holidays!$F$5:$G$33,2,FALSE)) | Z4: =IF(ISNA(VLOOKUP(Z$2,Holidays!$F$5:$G$33,2,FALSE)),"",VLOOKUP(Z$2,Holidays!$F$5:$G$33,2,FALSE)) | AB4: =IF(ISNA(VLOOKUP(AB$2,Holidays!$F$5:$G$33,2,FALSE)),"",VLOOKUP(AB$2,Holidays!$F$5:$G$33,2,FALSE)) | AD4: =IF(ISNA(VLOOKUP(AD$2,Holidays!$F$5:$G$33,2,FALSE)),"",VLOOKUP(AD$2,Holidays!$F$5:$G$33,2,FALSE)) | AF4: =IF(ISNA(VLOOKUP(AF$2,Holidays!$F$5:$G$33,2,FALSE)),"",VLOOKUP(AF$2,Holidays!$F$5:$G$33,2,FALSE)) | AH4: =IF(ISNA(VLOOKUP(AH$2,Holidays!$F$5:$G$33,2,FALSE)),"",VLOOKUP(AH$2,Holidays!$F$5:$G$33,2,FALSE)) | AJ4: =IF(ISNA(VLOOKUP(AJ$2,Holidays!$F$5:$G$33,2,FALSE)),"",VLOOKUP(AJ$2,Holidays!$F$5:$G$33,2,FALSE)) | AL4: =IF(ISNA(VLOOKUP(AL$2,Holidays!$F$5:$G$33,2,FALSE)),"",VLOOKUP(AL$2,Holidays!$F$5:$G$33,2,FALSE)) | AN4: =IF(ISNA(VLOOKUP(AN$2,Holidays!$F$5:$G$33,2,FALSE)),"",VLOOKUP(AN$2,Holidays!$F$5:$G$33,2,FALSE)) | AP4: =IF(ISNA(VLOOKUP(AP$2,Holidays!$F$5:$G$33,2,FALSE)),"",VLOOKUP(AP$2,Holidays!$F$5:$G$33,2,FALSE)) | AR4: =IF(ISNA(VLOOKUP(AR$2,Holidays!$F$5:$G$33,2,FALSE)),"",VLOOKUP(AR$2,Holidays!$F$5:$G$33,2,FALSE)) | AT4: =IF(ISNA(VLOOKUP(AT$2,Holidays!$F$5:$G$33,2,FALSE)),"",VLOOKUP(AT$2,Holidays!$F$5:$G$33,2,FALSE)) | AV4: =IF(ISNA(VLOOKUP(AV$2,Holidays!$F$5:$G$33,2,FALSE)),"",VLOOKUP(AV$2,Holidays!$F$5:$G$33,2,FALSE)) | AX4: =IF(ISNA(VLOOKUP(AX$2,Holidays!$F$5:$G$33,2,FALSE)),"",VLOOKUP(AX$2,Holidays!$F$5:$G$33,2,FALSE)) | AZ4: =IF(ISNA(VLOOKUP(AZ$2,Holidays!$F$5:$G$33,2,FALSE)),"",VLOOKUP(AZ$2,Holidays!$F$5:$G$33,2,FALSE)) | BB4: =IF(ISNA(VLOOKUP(BB$2,Holidays!$F$5:$G$33,2,FALSE)),"",VLOOKUP(BB$2,Holidays!$F$5:$G$33,2,FALSE)) | BD4: =IF(ISNA(VLOOKUP(BD$2,Holidays!$F$5:$G$33,2,FALSE)),"",VLOOKUP(BD$2,Holidays!$F$5:$G$33,2,FALSE)) | BF4: =IF(ISNA(VLOOKUP(BF$2,Holidays!$F$5:$G$33,2,FALSE)),"",VLOOKUP(BF$2,Holidays!$F$5:$G$33,2,FALSE)) | BH4: =IF(ISNA(VLOOKUP(BH$2,Holidays!$F$5:$G$33,2,FALSE)),"",VLOOKUP(BH$2,Holidays!$F$5:$G$33,2,FALSE)) | BJ4: =IF(ISNA(VLOOKUP(BJ$2,Holidays!$F$5:$G$33,2,FALSE)),"",VLOOKUP(BJ$2,Holidays!$F$5:$G$33,2,FALSE)) | BL4: =IF(ISNA(VLOOKUP(BL$2,Holidays!$F$5:$G$33,2,FALSE)),"",VLOOKUP(BL$2,Holidays!$F$5:$G$33,2,FALSE)) | BN4: =IF(ISNA(VLOOKUP(BN$2,Holidays!$F$5:$G$33,2,FALSE)),"",VLOOKUP(BN$2,Holidays!$F$5:$G$33,2,FALSE)) | BP4: =IF(ISNA(VLOOKUP(BP$2,Holidays!$F$5:$G$33,2,FALSE)),"",VLOOKUP(BP$2,Holidays!$F$5:$G$33,2,FALSE)) | BR4: =IF(ISNA(VLOOKUP(BR$2,Holidays!$F$5:$G$33,2,FALSE)),"",VLOOKUP(BR$2,Holidays!$F$5:$G$33,2,FALSE))
J5: Item | K5: Amount | L5: Item | M5: Amount | N5: Item | O5: Amount | P5: Item | Q5: Amount | R5: Item | S5: Amount | T5: Item | U5: Amount | V5: Item | W5: Amount | X5: Item | Y5: Amount | Z5: Item | AA5: Amount | AB5: Item | AC5: Amount | AD5: Item | AE5: Amount | AF5: Item | AG5: Amount | AH5: Item | AI5: Amount | AJ5: Item | AK5: Amount | AL5: Item | AM5: Amount | AN5: Item | AO5: Amount | AP5: Item | AQ5: Amount | AR5: Item | AS5: Amount | AT5: Item | AU5: Amount | AV5: Item | AW5: Amount | AX5: Item | AY5: Amount | AZ5: Item | BA5: Amount | BB5: Item | BC5: Amount | BD5: Item | BE5: Amount | BF5: Item | BG5: Amount | BH5: Item | BI5: Amount | BJ5: Item | BK5: Amount | BL5: Item | BM5: Amount | BN5: Item | BO5: Amount | BP5: Item | BQ5: Amount
